Workbook

Sheet Instructions
A1: =IFERROR(__xludf.dummyfunction("IMPORTRANGE(""1V5OIElI2MQo07KSlDqNMWMvWuTLDbyT-YC4EEx4A3Gw"", ""Live Instructions!A1:K123"")"),"Roller Derby Officiating Game History") -> Roller Derby Officiating Game History | J1: =IFERROR(__xludf.dummyfunction("""COMPUTED_VALUE"""),"") | K1: =IFERROR(__xludf.dummyfunction("""COMPUTED_VALUE"""),"")
A2: =IFERROR(__xludf.dummyfunction("""COMPUTED_VALUE"""),"Any roller derby Official may use this form. Use of this form does not imply affiliation with a WFTDA or MRDA league.") -> Any roller derby Official may use this form. Use of this form does not imply affiliation with a WFTDA or MRDA league.
A4: =IFERROR(__xludf.dummyfunction("""COMPUTED_VALUE"""),"How to use this form") -> How to use this form
A5: =IFERROR(__xludf.dummyfunction("""COMPUTED_VALUE"""),"• Make a copy of this Google document (File > Make a Copy ...) and name in the following format: ") -> • Make a copy of this Google document (File > Make a Copy ...) and name in the following format: | F5: =IFERROR(__xludf.dummyfunction("""COMPUTED_VALUE"""),"Officiating Name - Game History") -> Officiating Name - Game History | I5: =IFERROR(__xludf.dummyfunction("""COMPUTED_VALUE"""),"(Example: Jane Q Derby - Game History)") -> (Example: Jane Q Derby - Game History)
A6: =IFERROR(__xludf.dummyfunction("""COMPUTED_VALUE"""),"• Review this sample résumé to see examples of the below instructions:") -> • Review this sample résumé to see examples of the below instructions: | E6: =IFERROR(__xludf.dummyfunction("""COMPUTED_VALUE"""),"http://wftda.org/gh15ss") -> http://wftda.org/gh15ss
A8: =IFERROR(__xludf.dummyfunction("""COMPUTED_VALUE"""),"Instructions") -> Instructions
A9: =IFERROR(__xludf.dummyfunction("""COMPUTED_VALUE"""),"• DON'T DELETE ME! I'M IMPORTANT! Information on this tab is referenced by the other tabs in this Game History.") -> • DON'T DELETE ME! I'M IMPORTANT! Information on this tab is referenced by the other tabs in this Game History.
A10: =IFERROR(__xludf.dummyfunction("""COMPUTED_VALUE"""),"• Once you feel you have an adequate understanding of how to use this document, hide this tab by selecting the drop-down arrow at the right of the tab and select ""Hide sheet"".") -> • Once you feel you have an adequate understanding of how to use this document, hide this tab by selecting the drop-down arrow at the right of the tab and select "Hide sheet".
A12: =IFERROR(__xludf.dummyfunction("""COMPUTED_VALUE"""),"Summary") -> Summary
A13: =IFERROR(__xludf.dummyfunction("""COMPUTED_VALUE"""),"• The Summary page is a snapshot of your officiating history in the WFTDA and MRDA") -> • The Summary page is a snapshot of your officiating history in the WFTDA and MRDA
A14: =IFERROR(__xludf.dummyfunction("""COMPUTED_VALUE"""),"• Complete the personal information in rows 3 through 8.") -> • Complete the personal information in rows 3 through 8.
A15: =IFERROR(__xludf.dummyfunction("""COMPUTED_VALUE"""),"• Click on the pink ""Insert Photo Here"" image and choose ""Replace Image..."" in the available drop-down menu. To resize, hold the Shift key and drag the bottom right corner of image.") -> • Click on the pink "Insert Photo Here" image and choose "Replace Image..." in the available drop-down menu. To resize, hold the Shift key and drag the bottom right corner of image.
A16: =IFERROR(__xludf.dummyfunction("""COMPUTED_VALUE"""),"• Enter the details for any Officiating Clinics attended in their respective association tables. Specify any Ref- or NSO-focused training, the city and state/province, and the year attended.") -> • Enter the details for any Officiating Clinics attended in their respective association tables. Specify any Ref- or NSO-focused training, the city and state/province, and the year attended.
A17: =IFERROR(__xludf.dummyfunction("""COMPUTED_VALUE"""),"• Do not alter any other data below line 8. This information is automatically generated from the Game History. Making changes here will break your document formulas.") -> • Do not alter any other data below line 8. This information is automatically generated from the Game History. Making changes here will break your document formulas.
A19: =IFERROR(__xludf.dummyfunction("""COMPUTED_VALUE"""),"Game History") -> Game History
A20: =IFERROR(__xludf.dummyfunction("""COMPUTED_VALUE"""),"Event Details -") -> Event Details -
A21: =IFERROR(__xludf.dummyfunction("""COMPUTED_VALUE"""),"• DATE: Add new games at the top of your game history (above row 4). Format the date as YYYY-MM-DD. (This format is already set, so do not change it.)") -> • DATE: Add new games at the top of your game history (above row 4). Format the date as YYYY-MM-DD. (This format is already set, so do not change it.)
A22: =IFERROR(__xludf.dummyfunction("""COMPUTED_VALUE"""),"• TOURNAMENT: Enter the name of any multi-day tournament here. For all other games, leave this field blank.") -> • TOURNAMENT: Enter the name of any multi-day tournament here. For all other games, leave this field blank.
B23: =IFERROR(__xludf.dummyfunction("""COMPUTED_VALUE"""),"◦ If you were a Tournament Head Official or Games Officer, make one entry for the entire tournament rather than listing all the games held during that tournament.") -> ◦ If you were a Tournament Head Official or Games Officer, make one entry for the entire tournament rather than listing all the games held during that tournament.
A24: =IFERROR(__xludf.dummyfunction("""COMPUTED_VALUE"""),"• LOCATION: Enter the venue name and geographical location (city and state/province or, when outside North America, city and country).") -> • LOCATION: Enter the venue name and geographical location (city and state/province or, when outside North America, city and country).
A26: =IFERROR(__xludf.dummyfunction("""COMPUTED_VALUE"""),"Leagues and Teams -") -> Leagues and Teams -
A27: =IFERROR(__xludf.dummyfunction("""COMPUTED_VALUE"""),"• In all instances, enter the full name of the league. Do not abbreviate as numerous leagues have the same initials.") -> • In all instances, enter the full name of the league. Do not abbreviate as numerous leagues have the same initials.
A28: =IFERROR(__xludf.dummyfunction("""COMPUTED_VALUE"""),"• HOST LEAGUE: Enter the full name of the league hosting the game. This is often determined in the game contract, so do not presume based on the game location.") -> • HOST LEAGUE: Enter the full name of the league hosting the game. This is often determined in the game contract, so do not presume based on the game location.
A29: =IFERROR(__xludf.dummyfunction("""COMPUTED_VALUE"""),"• HOME TEAM/HIGHER SEED: Enter the full home league name and its team playing. Host Leagues are considered the home team if they are playing (unless specified otherwise in the game contract). If the Host League is not playing, the higher ranked team is c"&"onsidered the home team (unless specified otherwise in the game contract).") -> • HOME TEAM/HIGHER SEED: Enter the full home league name and its team playing. Host Leagues are considered the home team if they are playing (unless specified otherwise in the game contract). If the Host League is not playing, the higher ranked team is considered the home team (unless specified otherwise in the game contract).
B30: =IFERROR(__xludf.dummyfunction("""COMPUTED_VALUE"""),"◦ If the game was part of a tournament and you were a Head Official or Games Officer, leave this cell blank. Note the total number of games in the Notes cell.") -> ◦ If the game was part of a tournament and you were a Head Official or Games Officer, leave this cell blank. Note the total number of games in the Notes cell.
A31: =IFERROR(__xludf.dummyfunction("""COMPUTED_VALUE"""),"• VISITING TEAM/LOWER SEED: Enter the full visiting league name and its team playing. If the Host League is not playing, the lower ranked team is considered the visiting team (unless specified otherwise in the game contract).") -> • VISITING TEAM/LOWER SEED: Enter the full visiting league name and its team playing. If the Host League is not playing, the lower ranked team is considered the visiting team (unless specified otherwise in the game contract).
B32: =IFERROR(__xludf.dummyfunction("""COMPUTED_VALUE"""),"◦ If the game was part of a tournament and you were a Head Official or Games Officer, leave this cell blank.") -> ◦ If the game was part of a tournament and you were a Head Official or Games Officer, leave this cell blank.
A34: =IFERROR(__xludf.dummyfunction("""COMPUTED_VALUE"""),"Game Specifics -") -> Game Specifics -
A35: =IFERROR(__xludf.dummyfunction("""COMPUTED_VALUE"""),"• The terms that can be entered in these cells are restricted. If you attempt to use abbreviations not included in the charts below, you will receive an error message.") -> • The terms that can be entered in these cells are restricted. If you attempt to use abbreviations not included in the charts below, you will receive an error message.
A36: =IFERROR(__xludf.dummyfunction("""COMPUTED_VALUE"""),"• Data in these cells can be filtered so you can view more specific information within the game history. Use the drop-down menu in the column head to define your filter.") -> • Data in these cells can be filtered so you can view more specific information within the game history. Use the drop-down menu in the column head to define your filter.
A37: =IFERROR(__xludf.dummyfunction("""COMPUTED_VALUE"""),"• ASSOC: List the association abbreviation as defined in the Association chart below.") -> • ASSOC: List the association abbreviation as defined in the Association chart below.
B38: =IFERROR(__xludf.dummyfunction("""COMPUTED_VALUE"""),"◦ WFTDA: Games played between all-female teams, including WFTDA member/apprentice leagues and non-member/apprentice all-female teams that play by WFTDA rules.") -> ◦ WFTDA: Games played between all-female teams, including WFTDA member/apprentice leagues and non-member/apprentice all-female teams that play by WFTDA rules.
B39: =IFERROR(__xludf.dummyfunction("""COMPUTED_VALUE"""),"◦ MRDA: Games played between all-male teams or an all-male team versus any other team as long as the game follows the current MRDA rules.") -> ◦ MRDA: Games played between all-male teams or an all-male team versus any other team as long as the game follows the current MRDA rules.
B40: =IFERROR(__xludf.dummyfunction("""COMPUTED_VALUE"""),"◦ Flat Track-rules games played by non-association teams should be separated into the most appropriate association category. Co-ed games are marked as an ""Other"" game type for WFTDA and ""Regulation"" for MRDA. If you are unable to determine to your be"&"st judgment WFTDA or MRDA, default to MRDA.") -> ◦ Flat Track-rules games played by non-association teams should be separated into the most appropriate association category. Co-ed games are marked as an "Other" game type for WFTDA and "Regulation" for MRDA. If you are unable to determine to your best judgment WFTDA or MRDA, default to MRDA.
A41: =IFERROR(__xludf.dummyfunction("""COMPUTED_VALUE"""),"• TYPE: List the type of game played as defined in the Game Type chart below.") -> • TYPE: List the type of game played as defined in the Game Type chart below.
B42: =IFERROR(__xludf.dummyfunction("""COMPUTED_VALUE"""),"◦ If the game does not conform to any of the defined Game Types listed in the chart below, list the game on the Other History tab.") -> ◦ If the game does not conform to any of the defined Game Types listed in the chart below, list the game on the Other History tab.
A43: =IFERROR(__xludf.dummyfunction("""COMPUTED_VALUE"""),"• POSITION: List the position code of your role as defined in the Positions chart below. If you were a Head Official, enter T/C/HR or T/C/HNSO here.") -> • POSITION: List the position code of your role as defined in the Positions chart below. If you were a Head Official, enter T/C/HR or T/C/HNSO here.
A44: =IFERROR(__xludf.dummyfunction("""COMPUTED_VALUE"""),"• HO 2ND POSITION (IF APPLICABLE): If you were a Head Official working in another position (such as PBM or IPR), enter the code of that second position here.") -> • HO 2ND POSITION (IF APPLICABLE): If you were a Head Official working in another position (such as PBM or IPR), enter the code of that second position here.
A45: =IFERROR(__xludf.dummyfunction("""COMPUTED_VALUE"""),"• POSITIONAL SOFTWARE OPERATOR?: This pertains to positions that used Rinxter or software later endorsed to replace Rinxter (not league-coded apps). Mark this as") -> • POSITIONAL SOFTWARE OPERATOR?: This pertains to positions that used Rinxter or software later endorsed to replace Rinxter (not league-coded apps). Mark this as | K45: =IFERROR(__xludf.dummyfunction("""COMPUTED_VALUE"""),"Y") -> Y
A47: =IFERROR(__xludf.dummyfunction("""COMPUTED_VALUE"""),"Head Referee/Witness, Head NSO/Witness, and Details -") -> Head Referee/Witness, Head NSO/Witness, and Details -
...

Sheet Summary
A1: Flat Track Derby Game History Summary
A3: Official's Legal Name | C3: Alan Robertson | I3: Today's Date | J3: =TODAY() -> 46203
A4: Official's Derby Name | C4: Redacted | I4: Officiating Since | J4: 44807
A5: Affiliated League | C5: Central Coast Roller Derby United / Sydney Roller Derby League
A6: Insurance # | F6: Provider | H6: Skate Victoria
A7: Ref Cert Level | E7: Endorsement(s)
A8: NSO Cert Level | E8: Endorsement(s)
A10: WFTDA
A11: Skating Positions | C11: Code | D11: Game Designation | I11: Non-Skating Positions | J11: Code | K11: Game Designation
D12: Playoff | E12: Sanc | F12: Reg | G12: Other | K12: Playoff | L12: Sanc | M12: Reg | N12: Other
A13: Head Referee | C13: HR | D13: — | E13: =COUNTIFS('Game History'!G:G,"WFTDA",'Game History'!H:H,"Sanc",'Game History'!I:I,Instructions!A70) -> 0 | F13: =COUNTIFS('Game History'!G:G,"WFTDA",'Game History'!H:H,"Reg",'Game History'!I:I,Instructions!A70) -> 0 | G13: =COUNTIFS('Game History'!G:G,"WFTDA",'Game History'!H:H,"Other",'Game History'!I:I,Instructions!A70) -> 0 | I13: Head NSO | J13: HNSO | K13: — | L13: =COUNTIFS('Game History'!G:G,"WFTDA",'Game History'!H:H,"Sanc",'Game History'!I:I,Instructions!A73) -> 0 | M13: =COUNTIFS('Game History'!G:G,"WFTDA",'Game History'!H:H,"Reg",'Game History'!I:I,Instructions!A73) -> 0 | N13: =COUNTIFS('Game History'!G:G,"WFTDA",'Game History'!H:H,"Other",'Game History'!I:I,Instructions!A73) -> 0
A14: Jammer Referee | C14: JR | D14: =COUNTIFS('Game History'!G:G,"WFTDA",'Game History'!H:H,"Champs",'Game History'!I:I,Instructions!A74)+COUNTIFS('Game History'!G:G,"WFTDA",'Game History'!H:H,"Playoff",'Game History'!I:I,Instructions!A74) -> 0 | E14: =COUNTIFS('Game History'!G:G,"WFTDA",'Game History'!H:H,"Sanc",'Game History'!I:I,Instructions!A74) -> 2 | F14: =COUNTIFS('Game History'!G:G,"WFTDA",'Game History'!H:H,"Reg",'Game History'!I:I,Instructions!A74) -> 8 | G14: =COUNTIFS('Game History'!G:G,"WFTDA",'Game History'!H:H,"Other",'Game History'!I:I,Instructions!A74) -> 12 | I14: Penalty Tracker | J14: PT | K14: =COUNTIFS('Game History'!G:G,"WFTDA",'Game History'!H:H,"Champs",'Game History'!I:I,Instructions!A77)+COUNTIFS('Game History'!G:G,"WFTDA",'Game History'!H:H,"Playoff",'Game History'!I:I,Instructions!A77) -> 0 | L14: =COUNTIFS('Game History'!G:G,"WFTDA",'Game History'!H:H,"Sanc",'Game History'!I:I,Instructions!A77) -> 0 | M14: =COUNTIFS('Game History'!G:G,"WFTDA",'Game History'!H:H,"Reg",'Game History'!I:I,Instructions!A77) -> 2 | N14: =COUNTIFS('Game History'!G:G,"WFTDA",'Game History'!H:H,"Other",'Game History'!I:I,Instructions!A77) -> 2
A15: Inside Pack Referee | C15: IPR | D15: =COUNTIFS('Game History'!G:G,"WFTDA",'Game History'!H:H,"Champs",'Game History'!I:I,Instructions!A75)+COUNTIFS('Game History'!G:G,"WFTDA",'Game History'!H:H,"Playoff",'Game History'!I:I,Instructions!A75) -> 0 | E15: =COUNTIFS('Game History'!G:G,"WFTDA",'Game History'!H:H,"Sanc",'Game History'!I:I,Instructions!A75) -> 0 | F15: =COUNTIFS('Game History'!G:G,"WFTDA",'Game History'!H:H,"Reg",'Game History'!I:I,Instructions!A75) -> 8 | G15: =COUNTIFS('Game History'!G:G,"WFTDA",'Game History'!H:H,"Other",'Game History'!I:I,Instructions!A75) -> 0 | I15: Penalty Wrangler | J15: PW | K15: =COUNTIFS('Game History'!G:G,"WFTDA",'Game History'!H:H,"Champs",'Game History'!I:I,Instructions!A78)+COUNTIFS('Game History'!G:G,"WFTDA",'Game History'!H:H,"Playoff",'Game History'!I:I,Instructions!A78) -> 0 | L15: =COUNTIFS('Game History'!G:G,"WFTDA",'Game History'!H:H,"Sanc",'Game History'!I:I,Instructions!A78) -> 0 | M15: =COUNTIFS('Game History'!G:G,"WFTDA",'Game History'!H:H,"Reg",'Game History'!I:I,Instructions!A78) -> 0 | N15: =COUNTIFS('Game History'!G:G,"WFTDA",'Game History'!H:H,"Other",'Game History'!I:I,Instructions!A78) -> 0
A16: Outside Pack Referee | C16: OPR | D16: =COUNTIFS('Game History'!G:G,"WFTDA",'Game History'!H:H,"Champs",'Game History'!I:I,Instructions!A76)+COUNTIFS('Game History'!G:G,"WFTDA",'Game History'!H:H,"Playoff",'Game History'!I:I,Instructions!A76) -> 2 | E16: =COUNTIFS('Game History'!G:G,"WFTDA",'Game History'!H:H,"Sanc",'Game History'!I:I,Instructions!A76) -> 13 | F16: =COUNTIFS('Game History'!G:G,"WFTDA",'Game History'!H:H,"Reg",'Game History'!I:I,Instructions!A76) -> 25 | G16: =COUNTIFS('Game History'!G:G,"WFTDA",'Game History'!H:H,"Other",'Game History'!I:I,Instructions!A76) -> 5 | I16: Inside White Board | J16: IWB | K16: =COUNTIFS('Game History'!G:G,"WFTDA",'Game History'!H:H,"Champs",'Game History'!I:I,Instructions!A79)+COUNTIFS('Game History'!G:G,"WFTDA",'Game History'!H:H,"Playoff",'Game History'!I:I,Instructions!A79) -> 0 | L16: =COUNTIFS('Game History'!G:G,"WFTDA",'Game History'!H:H,"Sanc",'Game History'!I:I,Instructions!A79) -> 0 | M16: =COUNTIFS('Game History'!G:G,"WFTDA",'Game History'!H:H,"Reg",'Game History'!I:I,Instructions!A79) -> 0 | N16: =COUNTIFS('Game History'!G:G,"WFTDA",'Game History'!H:H,"Other",'Game History'!I:I,Instructions!A79) -> 0
A17: Alternate Referee | C17: ALTR | D17: =COUNTIFS('Game History'!G:G,"WFTDA",'Game History'!H:H,"Champs",'Game History'!I:I,Instructions!A87)+COUNTIFS('Game History'!G:G,"WFTDA",'Game History'!H:H,"Playoff",'Game History'!I:I,Instructions!A87) -> 0 | E17: =COUNTIFS('Game History'!G:G,"WFTDA",'Game History'!H:H,"Sanc",'Game History'!I:I,Instructions!A87) -> 1 | F17: =COUNTIFS('Game History'!G:G,"WFTDA",'Game History'!H:H,"Reg",'Game History'!I:I,Instructions!A87) -> 2 | G17: =COUNTIFS('Game History'!G:G,"WFTDA",'Game History'!H:H,"Other",'Game History'!I:I,Instructions!A87) -> 1 | I17: Outside White Board | J17: OWB | K17: =COUNTIFS('Game History'!G:G,"WFTDA",'Game History'!H:H,"Champs",'Game History'!I:I,Instructions!A80)+COUNTIFS('Game History'!G:G,"WFTDA",'Game History'!H:H,"Playoff",'Game History'!I:I,Instructions!A80) -> 0 | L17: =COUNTIFS('Game History'!G:G,"WFTDA",'Game History'!H:H,"Sanc",'Game History'!I:I,Instructions!A80) -> 0 | M17: =COUNTIFS('Game History'!G:G,"WFTDA",'Game History'!H:H,"Reg",'Game History'!I:I,Instructions!A80) -> 0 | N17: =COUNTIFS('Game History'!G:G,"WFTDA",'Game History'!H:H,"Other",'Game History'!I:I,Instructions!A80) -> 0
A18: Total Referee | D18: =SUM(D14:D17) -> 2 | E18: =SUM(E13:E17) -> 16 | F18: =SUM(F13:F17) -> 43 | G18: =SUM(G13:G17) -> 18 | I18: Jam Timer | J18: JT | K18: =COUNTIFS('Game History'!G:G,"WFTDA",'Game History'!H:H,"Champs",'Game History'!I:I,Instructions!A81)+COUNTIFS('Game History'!G:G,"WFTDA",'Game History'!H:H,"Playoff",'Game History'!I:I,Instructions!A81) -> 0 | L18: =COUNTIFS('Game History'!G:G,"WFTDA",'Game History'!H:H,"Sanc",'Game History'!I:I,Instructions!A81) -> 0 | M18: =COUNTIFS('Game History'!G:G,"WFTDA",'Game History'!H:H,"Reg",'Game History'!I:I,Instructions!A81) -> 5 | N18: =COUNTIFS('Game History'!G:G,"WFTDA",'Game History'!H:H,"Other",'Game History'!I:I,Instructions!A81) -> 0
I19: Scorekeeper | J19: SK | K19: =COUNTIFS('Game History'!G:G,"WFTDA",'Game History'!H:H,"Champs",'Game History'!I:I,Instructions!A82)+COUNTIFS('Game History'!G:G,"WFTDA",'Game History'!H:H,"Playoff",'Game History'!I:I,Instructions!A82) -> 0 | L19: =COUNTIFS('Game History'!G:G,"WFTDA",'Game History'!H:H,"Sanc",'Game History'!I:I,Instructions!A82) -> 2 | M19: =COUNTIFS('Game History'!G:G,"WFTDA",'Game History'!H:H,"Reg",'Game History'!I:I,Instructions!A82) -> 6 | N19: =COUNTIFS('Game History'!G:G,"WFTDA",'Game History'!H:H,"Other",'Game History'!I:I,Instructions!A82) -> 1
A20: Tournament Head Referee | C20: THR | D20: =COUNTIFS('Game History'!G:G,"WFTDA",'Game History'!H:H,"Champs",'Game History'!I:I,Instructions!A68)+COUNTIFS('Game History'!G:G,"WFTDA",'Game History'!H:H,"Playoff",'Game History'!I:I,Instructions!A68) -> 0 | E20: =COUNTIFS('Game History'!G:G,"WFTDA",'Game History'!H:H,"Sanc",'Game History'!I:I,Instructions!A68) -> 0 | F20: =COUNTIFS('Game History'!G:G,"WFTDA",'Game History'!H:H,"Reg",'Game History'!I:I,Instructions!A68) -> 0 | G20: =COUNTIFS('Game History'!G:G,"WFTDA",'Game History'!H:H,"Other",'Game History'!I:I,Instructions!A68) -> 0 | I20: Scoreboard Operator | J20: SO | K20: =COUNTIFS('Game History'!G:G,"WFTDA",'Game History'!H:H,"Champs",'Game History'!I:I,Instructions!A83)+COUNTIFS('Game History'!G:G,"WFTDA",'Game History'!H:H,"Playoff",'Game History'!I:I,Instructions!A83) -> 2 | L20: =COUNTIFS('Game History'!G:G,"WFTDA",'Game History'!H:H,"Sanc",'Game History'!I:I,Instructions!A83) -> 1 | M20: =COUNTIFS('Game History'!G:G,"WFTDA",'Game History'!H:H,"Reg",'Game History'!I:I,Instructions!A83) -> 16 | N20: =COUNTIFS('Game History'!G:G,"WFTDA",'Game History'!H:H,"Other",'Game History'!I:I,Instructions!A83) -> 3
A21: Crew Head Referee | C21: CHR | D21: =COUNTIFS('Game History'!G:G,"WFTDA",'Game History'!H:H,"Champs",'Game History'!I:I,Instructions!A69)+COUNTIFS('Game History'!G:G,"WFTDA",'Game History'!H:H,"Playoff",'Game History'!I:I,Instructions!A69)+COUNTIFS('Game History'!G:G,"WFTDA",'Game History'!H:H,"Champs",'Game History'!I:I,Instructions!A70)+COUNTIFS('Game History'!G:G,"WFTDA",'Game History'!H:H,"Playoff",'Game History'!I:I,Instructions!A70) -> 0 | E21: =COUNTIFS('Game History'!G:G,"WFTDA",'Game History'!H:H,"Sanc",'Game History'!I:I,Instructions!A69) -> 0 | F21: =COUNTIFS('Game History'!G:G,"WFTDA",'Game History'!H:H,"Reg",'Game History'!I:I,Instructions!A69) -> 0 | G21: =COUNTIFS('Game History'!G:G,"WFTDA",'Game History'!H:H,"Other",'Game History'!I:I,Instructions!A69) -> 0 | I21: Penalty Box Manager | J21: PBM | K21: =COUNTIFS('Game History'!G:G,"WFTDA",'Game History'!H:H,"Champs",'Game History'!I:I,Instructions!A84)+COUNTIFS('Game History'!G:G,"WFTDA",'Game History'!H:H,"Playoff",'Game History'!I:I,Instructions!A84) -> 0 | L21: =COUNTIFS('Game History'!G:G,"WFTDA",'Game History'!H:H,"Sanc",'Game History'!I:I,Instructions!A84) -> 0 | M21: =COUNTIFS('Game History'!G:G,"WFTDA",'Game History'!H:H,"Reg",'Game History'!I:I,Instructions!A84) -> 4 | N21: =COUNTIFS('Game History'!G:G,"WFTDA",'Game History'!H:H,"Other",'Game History'!I:I,Instructions!A84) -> 0
A22: Games Official | C22: GO | D22: =COUNTIFS('Game History'!G:G,"WFTDA",'Game History'!H:H,"Champs",'Game History'!I:I,Instructions!A67)+COUNTIFS('Game History'!G:G,"WFTDA",'Game History'!H:H,"Playoff",'Game History'!I:I,Instructions!A67) -> 0 | E22: =COUNTIFS('Game History'!G:G,"WFTDA",'Game History'!H:H,"Sanc",'Game History'!I:I,Instructions!A67) -> 0 | F22: =COUNTIFS('Game History'!G:G,"WFTDA",'Game History'!H:H,"Reg",'Game History'!I:I,Instructions!A67) -> 0 | G22: =COUNTIFS('Game History'!G:G,"WFTDA",'Game History'!H:H,"Other",'Game History'!I:I,Instructions!A67) -> 0 | I22: Penalty Box Timer | J22: PBT | K22: =COUNTIFS('Game History'!G:G,"WFTDA",'Game History'!H:H,"Champs",'Game History'!I:I,Instructions!A85)+COUNTIFS('Game History'!G:G,"WFTDA",'Game History'!H:H,"Playoff",'Game History'!I:I,Instructions!A85) -> 0 | L22: =COUNTIFS('Game History'!G:G,"WFTDA",'Game History'!H:H,"Sanc",'Game History'!I:I,Instructions!A85) -> 0 | M22: =COUNTIFS('Game History'!G:G,"WFTDA",'Game History'!H:H,"Reg",'Game History'!I:I,Instructions!A85) -> 12 | N22: =COUNTIFS('Game History'!G:G,"WFTDA",'Game History'!H:H,"Other",'Game History'!I:I,Instructions!A85) -> 9
A23: Tournament Head NSO | C23: THNSO | D23: =COUNTIFS('Game History'!G:G,"WFTDA",'Game History'!H:H,"Champs",'Game History'!I:I,Instructions!A71)+COUNTIFS('Game History'!G:G,"WFTDA",'Game History'!H:H,"Playoff",'Game History'!I:I,Instructions!A71) -> 0 | E23: =COUNTIFS('Game History'!G:G,"WFTDA",'Game History'!H:H,"Sanc",'Game History'!I:I,Instructions!A71) -> 0 | F23: =COUNTIFS('Game History'!G:G,"WFTDA",'Game History'!H:H,"Reg",'Game History'!I:I,Instructions!A71) -> 0 | G23: =COUNTIFS('Game History'!G:G,"WFTDA",'Game History'!H:H,"Other",'Game History'!I:I,Instructions!A71) -> 0 | I23: Lineup Tracker | J23: LT | K23: =COUNTIFS('Game History'!G:G,"WFTDA",'Game History'!H:H,"Champs",'Game History'!I:I,Instructions!A86)+COUNTIFS('Game History'!G:G,"WFTDA",'Game History'!H:H,"Playoff",'Game History'!I:I,Instructions!A86) -> 0 | L23: =COUNTIFS('Game History'!G:G,"WFTDA",'Game History'!H:H,"Sanc",'Game History'!I:I,Instructions!A86) -> 0 | M23: =COUNTIFS('Game History'!G:G,"WFTDA",'Game History'!H:H,"Reg",'Game History'!I:I,Instructions!A86) -> 2 | N23: =COUNTIFS('Game History'!G:G,"WFTDA",'Game History'!H:H,"Other",'Game History'!I:I,Instructions!A86) -> 0
A24: Crew Head NSO | C24: CHNSO | D24: =COUNTIFS('Game History'!G:G,"WFTDA",'Game History'!H:H,"Champs",'Game History'!I:I,Instructions!A72)+COUNTIFS('Game History'!G:G,"WFTDA",'Game History'!H:H,"Playoff",'Game History'!I:I,Instructions!A72)+COUNTIFS('Game History'!G:G,"WFTDA",'Game History'!H:H,"Champs",'Game History'!I:I,Instructions!A73)+COUNTIFS('Game History'!G:G,"WFTDA",'Game History'!H:H,"Playoff",'Game History'!I:I,Instructions!A73) -> 0 | E24: =COUNTIFS('Game History'!G:G,"WFTDA",'Game History'!H:H,"Sanc",'Game History'!I:I,Instructions!A72) -> 0 | F24: =COUNTIFS('Game History'!G:G,"WFTDA",'Game History'!H:H,"Reg",'Game History'!I:I,Instructions!A72) -> 0 | G24: =COUNTIFS('Game History'!G:G,"WFTDA",'Game History'!H:H,"Other",'Game History'!I:I,Instructions!A72) -> 0 | I24: Alternate NSO | J24: ALTN | K24: =COUNTIFS('Game History'!G:G,"WFTDA",'Game History'!H:H,"Champs",'Game History'!I:I,Instructions!A88)+COUNTIFS('Game History'!G:G,"WFTDA",'Game History'!H:H,"Playoff",'Game History'!I:I,Instructions!A88) -> 0 | L24: =COUNTIFS('Game History'!G:G,"WFTDA",'Game History'!H:H,"Sanc",'Game History'!I:I,Instructions!A88) -> 0 | M24: =COUNTIFS('Game History'!G:G,"WFTDA",'Game History'!H:H,"Reg",'Game History'!I:I,Instructions!A88) -> 0 | N24: =COUNTIFS('Game History'!G:G,"WFTDA",'Game History'!H:H,"Other",'Game History'!I:I,Instructions!A88) -> 0
I25: Total NSO | K25: =SUM(K14:K24) -> 2 | L25: =SUM(L13:L24) -> 3 | M25: =SUM(M13:M24) -> 47 | N25: =SUM(N13:N24) -> 15
A26: WFTDA Officiating Clinics attended | I26: Total Software Operator Game Experience | M26: =COUNTIFS('Game History'!G:G,"WFTDA",'Game History'!K:K,"Y") -> 0
A27: REF or NSO Track | B27: Location | C27: Year | D27: REF or NSO Track | E27: Location | G27: Year
I28: WFTDA Games Totals | K28: Current Rule Set | M28: Lifetime
K29: Referee | L29: NSO | M29: Referee | N29: NSO
K30: =SUM(D18:F18) -> 61 | L30: =SUM(K25:M25) -> 52 | M30: =SUM(D18:G18) -> 79 | N30: =SUM(K25:N25) -> 67
A33: MRDA
A34: Skating Positions | C34: Code | D34: Game Designation | I34: Non-Skating Positions | J34: Code | K34: Game Designation
D35: Playoff | E35: Sanc | F35: Reg | G35: Other | K35: Playoff | L35: Sanc | M35: Reg | N35: Other
A36: Head Referee | C36: HR | D36: — | E36: =COUNTIFS('Game History'!G:G,"MRDA",'Game History'!H:H,"Sanc",'Game History'!I:I,Instructions!A70) -> 0 | F36: =COUNTIFS('Game History'!G:G,"MRDA",'Game History'!H:H,"Reg",'Game History'!I:I,Instructions!A70) -> 0 | G36: =COUNTIFS('Game History'!G:G,"MRDA",'Game History'!H:H,"Other",'Game History'!I:I,Instructions!A70) -> 0 | I36: Head NSO | J36: HNSO | K36: — | L36: =COUNTIFS('Game History'!G:G,"MRDA",'Game History'!H:H,"Sanc",'Game History'!I:I,Instructions!A73) -> 0 | M36: =COUNTIFS('Game History'!G:G,"MRDA",'Game History'!H:H,"Reg",'Game History'!I:I,Instructions!A73) -> 0 | N36: =COUNTIFS('Game History'!G:G,"MRDA",'Game History'!H:H,"Other",'Game History'!I:I,Instructions!A73) -> 0
A37: Jammer Referee | C37: JR | D37: =COUNTIFS('Game History'!G:G,"MRDA",'Game History'!H:H,"Champs",'Game History'!I:I,Instructions!A74)+COUNTIFS('Game History'!G:G,"MRDA",'Game History'!H:H,"Playoff",'Game History'!I:I,Instructions!A74) -> 0 | E37: =COUNTIFS('Game History'!G:G,"MRDA",'Game History'!H:H,"Sanc",'Game History'!I:I,Instructions!A74) -> 0 | F37: =COUNTIFS('Game History'!G:G,"MRDA",'Game History'!H:H,"Reg",'Game History'!I:I,Instructions!A74) -> 0 | G37: =COUNTIFS('Game History'!G:G,"MRDA",'Game History'!H:H,"Other",'Game History'!I:I,Instructions!A74) -> 0 | I37: Penalty Tracker | J37: PT | K37: =COUNTIFS('Game History'!G:G,"MRDA",'Game History'!H:H,"Champs",'Game History'!I:I,Instructions!A77)+COUNTIFS('Game History'!G:G,"MRDA",'Game History'!H:H,"Playoff",'Game History'!I:I,Instructions!A77) -> 0 | L37: =COUNTIFS('Game History'!G:G,"MRDA",'Game History'!H:H,"Sanc",'Game History'!I:I,Instructions!A77) -> 0 | M37: =COUNTIFS('Game History'!G:G,"MRDA",'Game History'!H:H,"Reg",'Game History'!I:I,Instructions!A77) -> 0 | N37: =COUNTIFS('Game History'!G:G,"MRDA",'Game History'!H:H,"Other",'Game History'!I:I,Instructions!A77) -> 0
A38: Inside Pack Referee | C38: IPR | D38: =COUNTIFS('Game History'!G:G,"MRDA",'Game History'!H:H,"Champs",'Game History'!I:I,Instructions!A75)+COUNTIFS('Game History'!G:G,"MRDA",'Game History'!H:H,"Playoff",'Game History'!I:I,Instructions!A75) -> 0 | E38: =COUNTIFS('Game History'!G:G,"MRDA",'Game History'!H:H,"Sanc",'Game History'!I:I,Instructions!A75) -> 0 | F38: =COUNTIFS('Game History'!G:G,"MRDA",'Game History'!H:H,"Reg",'Game History'!I:I,Instructions!A75) -> 0 | G38: =COUNTIFS('Game History'!G:G,"MRDA",'Game History'!H:H,"Other",'Game History'!I:I,Instructions!A75) -> 0 | I38: Penalty Wrangler | J38: PW | K38: =COUNTIFS('Game History'!G:G,"MRDA",'Game History'!H:H,"Champs",'Game History'!I:I,Instructions!A78)+COUNTIFS('Game History'!G:G,"MRDA",'Game History'!H:H,"Playoff",'Game History'!I:I,Instructions!A78) -> 0 | L38: =COUNTIFS('Game History'!G:G,"MRDA",'Game History'!H:H,"Sanc",'Game History'!I:I,Instructions!A78) -> 0 | M38: =COUNTIFS('Game History'!G:G,"MRDA",'Game History'!H:H,"Reg",'Game History'!I:I,Instructions!A78) -> 0 | N38: =COUNTIFS('Game History'!G:G,"MRDA",'Game History'!H:H,"Other",'Game History'!I:I,Instructions!A78) -> 0
A39: Outside Pack Referee | C39: OPR | D39: =COUNTIFS('Game History'!G:G,"MRDA",'Game History'!H:H,"Champs",'Game History'!I:I,Instructions!A76)+COUNTIFS('Game History'!G:G,"MRDA",'Game History'!H:H,"Playoff",'Game History'!I:I,Instructions!A76) -> 0 | E39: =COUNTIFS('Game History'!G:G,"MRDA",'Game History'!H:H,"Sanc",'Game History'!I:I,Instructions!A76) -> 0 | F39: =COUNTIFS('Game History'!G:G,"MRDA",'Game History'!H:H,"Reg",'Game History'!I:I,Instructions!A76) -> 0 | G39: =COUNTIFS('Game History'!G:G,"MRDA",'Game History'!H:H,"Other",'Game History'!I:I,Instructions!A76) -> 0 | I39: Inside White Board | J39: IWB | K39: =COUNTIFS('Game History'!G:G,"MRDA",'Game History'!H:H,"Champs",'Game History'!I:I,Instructions!A79)+COUNTIFS('Game History'!G:G,"MRDA",'Game History'!H:H,"Playoff",'Game History'!I:I,Instructions!A79) -> 0 | L39: =COUNTIFS('Game History'!G:G,"MRDA",'Game History'!H:H,"Sanc",'Game History'!I:I,Instructions!A79) -> 0 | M39: =COUNTIFS('Game History'!G:G,"MRDA",'Game History'!H:H,"Reg",'Game History'!I:I,Instructions!A79) -> 0 | N39: =COUNTIFS('Game History'!G:G,"MRDA",'Game History'!H:H,"Other",'Game History'!I:I,Instructions!A79) -> 0
A40: Alternate Referee | C40: ALTR | D40: =COUNTIFS('Game History'!G:G,"MRDA",'Game History'!H:H,"Champs",'Game History'!I:I,Instructions!A87)+COUNTIFS('Game History'!G:G,"MRDA",'Game History'!H:H,"Playoff",'Game History'!I:I,Instructions!A87) -> 0 | E40: =COUNTIFS('Game History'!G:G,"MRDA",'Game History'!H:H,"Sanc",'Game History'!I:I,Instructions!A87) -> 0 | F40: =COUNTIFS('Game History'!G:G,"MRDA",'Game History'!H:H,"Reg",'Game History'!I:I,Instructions!A87) -> 0 | G40: =COUNTIFS('Game History'!G:G,"MRDA",'Game History'!H:H,"Other",'Game History'!I:I,Instructions!A87) -> 0 | I40: Outside White Board | J40: OWB | K40: =COUNTIFS('Game History'!G:G,"MRDA",'Game History'!H:H,"Champs",'Game History'!I:I,Instructions!A80)+COUNTIFS('Game History'!G:G,"MRDA",'Game History'!H:H,"Playoff",'Game History'!I:I,Instructions!A80) -> 0 | L40: =COUNTIFS('Game History'!G:G,"MRDA",'Game History'!H:H,"Sanc",'Game History'!I:I,Instructions!A80) -> 0 | M40: =COUNTIFS('Game History'!G:G,"MRDA",'Game History'!H:H,"Reg",'Game History'!I:I,Instructions!A80) -> 0 | N40: =COUNTIFS('Game History'!G:G,"MRDA",'Game History'!H:H,"Other",'Game History'!I:I,Instructions!A80) -> 0
A41: Total Referee | D41: =SUM(D36:D40) -> 0 | E41: =SUM(E36:E40) -> 0 | F41: =SUM(F36:F40) -> 0 | G41: =SUM(G36:G40) -> 0 | I41: Jam Timer | J41: JT | K41: =COUNTIFS('Game History'!G:G,"MRDA",'Game History'!H:H,"Champs",'Game History'!I:I,Instructions!A81)+COUNTIFS('Game History'!G:G,"MRDA",'Game History'!H:H,"Playoff",'Game History'!I:I,Instructions!A81) -> 0 | L41: =COUNTIFS('Game History'!G:G,"MRDA",'Game History'!H:H,"Sanc",'Game History'!I:I,Instructions!A81) -> 0 | M41: =COUNTIFS('Game History'!G:G,"MRDA",'Game History'!H:H,"Reg",'Game History'!I:I,Instructions!A81) -> 0 | N41: =COUNTIFS('Game History'!G:G,"MRDA",'Game History'!H:H,"Other",'Game History'!I:I,Instructions!A81) -> 0
I42: Scorekeeper | J42: SK | K42: =COUNTIFS('Game History'!G:G,"MRDA",'Game History'!H:H,"Champs",'Game History'!I:I,Instructions!A82)+COUNTIFS('Game History'!G:G,"MRDA",'Game History'!H:H,"Playoff",'Game History'!I:I,Instructions!A82) -> 0 | L42: =COUNTIFS('Game History'!G:G,"MRDA",'Game History'!H:H,"Sanc",'Game History'!I:I,Instructions!A82) -> 0 | M42: =COUNTIFS('Game History'!G:G,"MRDA",'Game History'!H:H,"Reg",'Game History'!I:I,Instructions!A82) -> 0 | N42: =COUNTIFS('Game History'!G:G,"MRDA",'Game History'!H:H,"Other",'Game History'!I:I,Instructions!A82) -> 0
A43: Tournament Head Referee | C43: THR | D43: =COUNTIFS('Game History'!G:G,"MRDA",'Game History'!H:H,"Champs",'Game History'!I:I,Instructions!A68)+COUNTIFS('Game History'!G:G,"MRDA",'Game History'!H:H,"Playoff",'Game History'!I:I,Instructions!A68) -> 0 | E43: =COUNTIFS('Game History'!G:G,"MRDA",'Game History'!H:H,"Sanc",'Game History'!I:I,Instructions!A68) -> 0 | F43: =COUNTIFS('Game History'!G:G,"MRDA",'Game History'!H:H,"Reg",'Game History'!I:I,Instructions!A68) -> 0 | G43: =COUNTIFS('Game History'!G:G,"MRDA",'Game History'!H:H,"Other",'Game History'!I:I,Instructions!A68) -> 0 | I43: Scoreboard Operator | J43: SO | K43: =COUNTIFS('Game History'!G:G,"MRDA",'Game History'!H:H,"Champs",'Game History'!I:I,Instructions!A83)+COUNTIFS('Game History'!G:G,"MRDA",'Game History'!H:H,"Playoff",'Game History'!I:I,Instructions!A83) -> 0 | L43: =COUNTIFS('Game History'!G:G,"MRDA",'Game History'!H:H,"Sanc",'Game History'!I:I,Instructions!A83) -> 0 | M43: =COUNTIFS('Game History'!G:G,"MRDA",'Game History'!H:H,"Reg",'Game History'!I:I,Instructions!A83) -> 1 | N43: =COUNTIFS('Game History'!G:G,"MRDA",'Game History'!H:H,"Other",'Game History'!I:I,Instructions!A83) -> 0
A44: Crew Head Referee | C44: CHR | D44: =COUNTIFS('Game History'!G:G,"MRDA",'Game History'!H:H,"Champs",'Game History'!I:I,Instructions!A69)+COUNTIFS('Game History'!G:G,"MRDA",'Game History'!H:H,"Playoff",'Game History'!I:I,Instructions!A69)+COUNTIFS('Game History'!G:G,"MRDA",'Game History'!H:H,"Champs",'Game History'!I:I,Instructions!A70)+COUNTIFS('Game History'!G:G,"MRDA",'Game History'!H:H,"Playoff",'Game History'!I:I,Instructions!A70) -> 0 | E44: =COUNTIFS('Game History'!G:G,"MRDA",'Game History'!H:H,"Sanc",'Game History'!I:I,Instructions!A69) -> 0 | F44: =COUNTIFS('Game History'!G:G,"MRDA",'Game History'!H:H,"Reg",'Game History'!I:I,Instructions!A69) -> 0 | G44: =COUNTIFS('Game History'!G:G,"MRDA",'Game History'!H:H,"Other",'Game History'!I:I,Instructions!A69) -> 0 | I44: Penalty Box Manager | J44: PBM | K44: =COUNTIFS('Game History'!G:G,"MRDA",'Game History'!H:H,"Champs",'Game History'!I:I,Instructions!A84)+COUNTIFS('Game History'!G:G,"MRDA",'Game History'!H:H,"Playoff",'Game History'!I:I,Instructions!A84) -> 0 | L44: =COUNTIFS('Game History'!G:G,"MRDA",'Game History'!H:H,"Sanc",'Game History'!I:I,Instructions!A84) -> 0 | M44: =COUNTIFS('Game History'!G:G,"MRDA",'Game History'!H:H,"Reg",'Game History'!I:I,Instructions!A84) -> 0 | N44: =COUNTIFS('Game History'!G:G,"MRDA",'Game History'!H:H,"Other",'Game History'!I:I,Instructions!A84) -> 0
...

Sheet Game History
B1: Game and Officiating Position History
B2: Event Details | D2: Leagues and Teams | I2: Game Specifics | L2: Head Referee/Witness | M2: Head NSO/Witness | N2: Notes
A3: Date | B3: Tournament | C3: Location | D3: Host League | E3: Home Team/Higher Seed | F3: Visiting Team/Lower Seed | G3: Assoc | H3: Type | I3: Position | J3: HO 2nd Position (if applicable) | K3: Positional Software Operator? | O3: =COUNT(O4:O2000) -> 150
A4: 44807 | B4: 5x5 | C4: Blue Mountains, NSW, Australia | D4: Blue Mountains Roller Derby League | E4: Sydney Roller Derby League (Velociraptors) | F4: Newcastle Roller Derby League | G4: WFTDA | H4: Reg | I4: SK | L4: John Ref Kennedy | O4: 1 | P4: =COUNT(O4:O12) -> 9
A5: 44822 | B5: Inner West 10th Birthday | C5: Sydney Boys High, Sydney | D5: Inner West Roller Derby League | E5: Inner West Roller Derby League | F5: Northern Beaches Roller Derby League | G5: WFTDA | H5: Reg | I5: LT | L5: John Ref Kennedy | M5: Ritual Ideas | N5: Joint PT/LT position | O5: 2
A6: 44822 | B6: Inner West 10th Birthday | C6: Sydney Boys High, Sydney | D6: Inner West Roller Derby League | E6: Sydney Roller Derby League (Velociraptors) | F6: Inner West Roller Derby League | G6: WFTDA | H6: Reg | I6: PBM | L6: The Spanish Inquisition | M6: Ritual Ideas | O6: 3
A7: 44822 | B7: Inner West 10th Birthday | C7: Sydney Boys High, Sydney | D7: Inner West Roller Derby League | E7: Sydney Roller Derby League (Velociraptors) | F7: Inner West Roller Derby League | G7: WFTDA | H7: Reg | I7: PBM | L7: John Ref Kennedy | M7: Ritual Ideas | O7: 4
A8: 44863 | B8: 5x5 | C8: Windsor, NSW | D8: Blue Mountains Roller Derby League | E8: Central Coast Roller Derby League / S2D2 | F8: Northern Beaches Roller Derby League | G8: WFTDA | H8: Reg | I8: PBT | L8: Clareful Consideration | M8: Bellows | O8: 5
A9: 44863 | B9: 5x5 | C9: Windsor, NSW | D9: Blue Mountains Roller Derby League | E9: Sydney Roller Derby League (Velociraptors) | F9: Canberra Roller Derby League / Varsity Roller Derby League | G9: WFTDA | H9: Reg | I9: SK | L9: Jim Peccable | M9: Leo Slayer | O9: 6
A10: 44878 | B10: Jurassic Packs | C10: Bass Hill Velodrome, Sydney | D10: Sydney Roller Derby League | E10: Potluck | F10: Potluck | G10: WFTDA | H10: Other | I10: SK | L10: Denominator | M10: Nasty Surprise | O10: 7
A11: 44878 | B11: Jurassic Packs | C11: Bass Hill Velodrome, Sydney Australia | D11: Sydney Roller Derby League | E11: Potluck | F11: Potluck | G11: WFTDA | H11: Other | I11: SO | L11: Bones | M11: Ritual Ideas | O11: 8
A12: 44878 | B12: Jurassic Packs | C12: Bass Hill Velodrome, Sydney Australia | D12: Sydney Roller Derby League | E12: Potluck | F12: Potluck | G12: WFTDA | H12: Other | I12: PT | L12: The Spanish Inquisition | M12: Sparkles | N12: Joint PT/LT position | O12: 9
A13: 44974 | B13: Pride Fight | C13: Sydney | D13: Sydney Roller Derby League | E13: Rainbows | F13: Sparkles | G13: WFTDA | H13: Other | I13: PBT | L13: The Spanish Inquisition | M13: Ritual Ideas | O13: 10 | P13: =COUNT(O13:O45) -> 33
A14: 44974 | B14: Pride Fight | C14: Sydney | D14: Sydney Roller Derby League | E14: Butch | F14: Femme | G14: WFTDA | H14: Other | I14: PT | L14: Denominator | M14: Nasty Surprise | N14: Joint PT/LT position | O14: 11
A15: 45003 | B15: Northern Rivers Revolt | C15: Byron Bay, Australia | D15: Tweed Valley Rollers | E15: Brisbane City Rollers (Red Kennedys) | F15: Sydney Roller Derby League (Snipers) | G15: WFTDA | H15: Reg | I15: PBT | L15: John Ref Kennedy | O15: 12
A16: 45003 | B16: Northern Rivers Revolt | C16: Byron Bay, Australia | D16: Tweed Valley Rollers | E16: Northern Beaches (Sirens) | F16: Van Diemens | G16: WFTDA | H16: Reg | I16: PBT | L16: John Ref Kennedy | O16: 13
A17: 45003 | B17: Northern Rivers Revolt | C17: Byron Bay, Australia | D17: Tweed Valley Rollers | E17: Van Diemens | F17: Sydney Roller Derby League (Snipers) | G17: WFTDA | H17: Reg | I17: PBT | L17: John Ref Kennedy | O17: 14
A18: 45003 | B18: Northern Rivers Revolt | C18: Byron Bay, Australia | D18: Tweed Valley Rollers | E18: South Seas Roller Derby (Banshees) | F18: Northern Beaches Roller Derby (Sirens) | G18: WFTDA | H18: Reg | I18: PBT | L18: John Ref Kennedy | O18: 15
A19: 45004 | B19: Northern Rivers Revolt | C19: Byron Bay, Australia | D19: Tweed Valley Rollers | E19: Brisbane City Rollers (Red Kennedys) | F19: River Valley Rollers | G19: WFTDA | H19: Reg | I19: PBT | L19: John Ref Kennedy | O19: 16
A20: 45004 | B20: Northern Rivers Revolt | C20: Byron Bay, Australia | D20: Tweed Valley Rollers | E20: Sydney Roller Derby League (Velociraptors) | F20: Northern Beaches Roller Derby | G20: WFTDA | H20: Reg | I20: PBT | L20: John Ref Kennedy | O20: 17
A21: 45004 | B21: Northern Rivers Revolt | C21: Byron Bay, Australia | D21: Tweed Valley Rollers | E21: River Valley Rollers | F21: Van Diemens | G21: WFTDA | H21: Reg | I21: PBT | L21: John Ref Kennedy | O21: 18
A22: 45004 | B22: Northern Rivers Revolt | C22: Byron Bay, Australia | D22: Tweed Valley Rollers | E22: Sydney Roller Derby League (Velociraptors) | F22: South Seas Roller Derby (Banshees) | G22: WFTDA | H22: Reg | I22: PBT | L22: John Ref Kennedy | O22: 19
A23: 45031 | B23: 5x5 | C23: Sydney, Australia | D23: Inner West Roller Derby League | E23: Inner West Roller Derby League | F23: Northern Beaches Roller Derby | G23: WFTDA | H23: Reg | I23: SO | L23: Jim Peccable | M23: Ritual Ideas | O23: 20
A24: 45066 | B24: 5x5 | C24: Newcastle, Australia | D24: Newcastle Roller Derby League | E24: Inner West Roller Derby League B | F24: Western Sydney Rollers / South Side Derby | G24: WFTDA | H24: Reg | I24: SO | L24: Clareful Consideration | M24: Vengeful Vixen | O24: 21
A25: 45066 | B25: 5x5 | C25: Newcastle, Australia | D25: Newcastle Roller Derby League | E25: Newcastle Roller Derby League | F25: Inner West Roller Derby League | G25: WFTDA | H25: Reg | I25: PT | L25: Jim Peccable | M25: Seath Lord | N25: Joint PT/LT position | O25: 22
A26: 45081 | B26: 5x5 | C26: Sydney, Australia | D26: Maitland Roller Derby League | E26: Varsity Derby League | F26: Sydney Roller Derby League (Velociraptors) | G26: WFTDA | H26: Reg | I26: JT | L26: Jim Peccable | M26: Leo Slayer | O26: 23
A27: 2023-07-01 | B27: ERRD Smackdown Tournament 2023 | C27: PCYC Hawkesbury - Sydney, Australia | D27: Western Sydney Rollers | E27: CRASH Mixed Gender Roller Derby - The Ultimate Incredibles | F27: Toowoomba City Rollers - Quad Squad | G27: WFTDA | H27: Other | I27: OPR | L27: Clareful Consideration | M27: Body BagHer | N27: THR - John Ref. Kennedy / THNSO - Switzerland | O27: 24
A28: 2023-07-01 | B28: ERRD Smackdown Tournament 2023 | C28: PCYC Hawkesbury - Sydney, Australia | D28: Western Sydney Rollers | E28: Northern Beaches Roller Derby League - Sirens | F28: Sydney Roller Derby League - Velociraptors | G28: WFTDA | H28: Reg | I28: OPR | L28: Clareful Consideration | M28: Body BagHer | N28: THR - John Ref. Kennedy / THNSO - Switzerland | O28: 25
A29: 2023-07-01 | B29: ERRD Smackdown Tournament 2023 | C29: PCYC Hawkesbury - Sydney, Australia | D29: Western Sydney Rollers | E29: Newcastle Roller Derby League - Dockyard Dames | F29: Eastern Region Roller Derby - ERRaDicators | G29: WFTDA | H29: Reg | I29: JR | L29: Clareful Consideration | M29: Body BagHer | O29: 26
A30: 2023-07-01 | B30: ERRD Smackdown Tournament 2023 | C30: PCYC Hawkesbury - Sydney, Australia | D30: Western Sydney Rollers | E30: Northern Beaches Roller Derby League - Sirens | F30: Inner West Roller Derby League - Bamshees | G30: WFTDA | H30: Reg | I30: PT | L30: Jim Peccable | M30: Switzerland | N30: Joint PT/LT position | O30: 27
A31: 2023-07-01 | B31: ERRD Smackdown Tournament 2023 | C31: PCYC Hawkesbury - Sydney, Australia | D31: Western Sydney Rollers | E31: Newcastle Junior Roller Derby - The Combos | F31: Toowoomba City Rollers - Range Rascals | G31: WFTDA | H31: Other | I31: JR | L31: Clareful Consideration | M31: Vixen | N31: Juniors Game, Level 4 | O31: 28
A32: 2023-07-01 | B32: ERRD Smackdown Tournament 2023 | C32: PCYC Hawkesbury - Sydney, Australia | D32: Western Sydney Rollers | E32: Wollongong Illawarra Roller Derby League - Steel City Derby Dolls | F32: Central Coast Roller Derby United - Asgardians | G32: WFTDA | H32: Reg | I32: OPR | L32: Jim Peccable | M32: Switzerland | O32: 29
A33: 2023-07-02 | B33: ERRD Smackdown Tournament 2023 | C33: PCYC Hawkesbury - Sydney, Australia | D33: Western Sydney Rollers | E33: Newcastle Roller Derby League - Dockyard Dames | F33: Eastern Region Roller Derby - ERRaDicators | G33: WFTDA | H33: Reg | I33: OPR | L33: Clareful Consideration | M33: Body BagHer | O33: 30
A34: 2023-07-02 | B34: ERRD Smackdown Tournament 2023 | C34: PCYC Hawkesbury - Sydney, Australia | D34: Western Sydney Rollers | E34: CRASH Mixed Gender Roller Derby - The Ultimate Incredibles | F34: Inner West Roller Derby League - Skatecrashers | G34: WFTDA | H34: Other | I34: OPR | L34: Clareful Consideration | M34: Body BagHer | O34: 31
A35: 2023-07-02 | B35: ERRD Smackdown Tournament 2023 | C35: PCYC Hawkesbury - Sydney, Australia | D35: Western Sydney Rollers | E35: Canberra Roller Derby League - Vice City Rollers | F35: CRASH Mixed Gender Roller Derby - The Ultimate Incredibles | G35: WFTDA | H35: Other | I35: OPR | L35: Spanish Inquisition | M35: Dinotello TR2 | O35: 32
A36: 2024-07-23 | B36: Fundays Round 1 2023 | C36: Dunc Gray Velodrome, Bass Hill NSW, Australia | D36: Sydney Roller Derby League | E36: The Young and the Rest of Us | F36: Baby got Back Blocks | G36: WFTDA | H36: Other | I36: JR | L36: Spanish Inquisition | M36: Nasty Surprise | O36: 33
A37: 45144 | B37: 5x5 | C37: Sydney, Australia | D37: Inner West Roller Derby League | E37: Northern Beaches (Sirens) | F37: Blue Mountains Roller Derby League | G37: WFTDA | H37: Reg | I37: SK | L37: Snarls Dickens | M37: Even Stephen | O37: 34
A38: 45144 | B38: 5x5 | C38: Sydney, Australia | D38: Inner West Roller Derby League | E38: Newcastle Roller Derby League | F38: Sydney Roller Derby League ( | G38: WFTDA | H38: Reg | I38: JT | L38: Denominator | M38: Seath Lord | O38: 35
A39: 45158 | B39: Fundays Round 2 2023 | C39: Dunc Gray Velodrome, Bass Hill NSW, Australia | D39: Sydney Roller Derby League | E39: A League of their Bones | F39: Baby got Back Blocks | G39: WFTDA | H39: Other | I39: JR | O39: 36
A40: 45178 | B40: 5x5 | C40: Denman Prospect, ACT | D40: Varsity Roller Derby League | E40: Western Sydney Rollers / South Side Derby League | F40: Northern Beaches Roller Derby | G40: WFTDA | H40: Reg | I40: SO | L40: John Ref Kennedy | M40: Leo Slayer | O40: 37
...

Sheet Annuals
A1: Annual Totals by Position
A2: WFTDA Referee
A4: 1 YEAR | B4: Playoff | C4: Sanc | D4: Reg | E4: Total | H4: 18 MONTHS | I4: Playoff | J4: Sanc | K4: Reg | L4: Total
A5: THR | B5: =COUNTIFS('Game History'!A:A,(">"&(TODAY()-365)),'Game History'!G:G,"WFTDA",'Game History'!H:H,"Champs",'Game History'!I:I,Instructions!A68)+COUNTIFS('Game History'!A:A,(">"&(TODAY()-365)),'Game History'!G:G,"WFTDA",'Game History'!H:H,"Playoff",'Game History'!I:I,Instructions!A68) -> 0 | C5: =COUNTIFS('Game History'!A:A,(">"&(TODAY()-365)),'Game History'!G:G,"WFTDA",'Game History'!H:H,"Sanc",'Game History'!I:I,Instructions!A68) -> 0 | D5: =COUNTIFS('Game History'!A:A,(">"&(TODAY()-365)),'Game History'!G:G,"WFTDA",'Game History'!H:H,"Reg",'Game History'!I:I,Instructions!A68) -> 0 | E5: =SUM(B5,C5,D5) -> 0 | H5: THR | I5: =COUNTIFS('Game History'!A:A,(">"&(TODAY()-548)),'Game History'!G:G,"WFTDA",'Game History'!H:H,"Champs",'Game History'!I:I,Instructions!A68)+COUNTIFS('Game History'!A:A,(">"&(TODAY()-548)),'Game History'!G:G,"WFTDA",'Game History'!H:H,"Playoff",'Game History'!I:I,Instructions!A68) -> 0 | J5: =COUNTIFS('Game History'!A:A,(">"&(TODAY()-548)),'Game History'!G:G,"WFTDA",'Game History'!H:H,"Sanc",'Game History'!I:I,Instructions!A68) -> 0 | K5: =COUNTIFS('Game History'!A:A,(">"&(TODAY()-548)),'Game History'!G:G,"WFTDA",'Game History'!H:H,"Reg",'Game History'!I:I,Instructions!A68) -> 0 | L5: =SUM(I5,J5,K5) -> 0
A6: CHR | B6: =COUNTIFS('Game History'!A:A,(">"&(TODAY()-365)),'Game History'!G:G,"WFTDA",'Game History'!H:H,"Champs",'Game History'!I:I,Instructions!A69)+COUNTIFS('Game History'!A:A,(">"&(TODAY()-365)),'Game History'!G:G,"WFTDA",'Game History'!H:H,"Playoff",'Game History'!I:I,Instructions!A69)+COUNTIFS('Game History'!A:A,(">"&(TODAY()-365)),'Game History'!G:G,"WFTDA",'Game History'!H:H,"Champs",'Game History'!I:I,Instructions!A70)+COUNTIFS('Game History'!A:A,(">"&(TODAY()-365)),'Game History'!G:G,"WFTDA",'Game History'!H:H,"Playoff",'Game History'!I:I,Instructions!A70) -> 0 | C6: =COUNTIFS('Game History'!A:A,(">"&(TODAY()-365)),'Game History'!G:G,"WFTDA",'Game History'!H:H,"Sanc",'Game History'!I:I,Instructions!A69) -> 0 | D6: =COUNTIFS('Game History'!A:A,(">"&(TODAY()-365)),'Game History'!G:G,"WFTDA",'Game History'!H:H,"Reg",'Game History'!I:I,Instructions!A69) -> 0 | E6: =SUM(B6,C6,D6) -> 0 | H6: CHR | I6: =COUNTIFS('Game History'!A:A,(">"&(TODAY()-548)),'Game History'!G:G,"WFTDA",'Game History'!H:H,"Champs",'Game History'!I:I,Instructions!A69)+COUNTIFS('Game History'!A:A,(">"&(TODAY()-548)),'Game History'!G:G,"WFTDA",'Game History'!H:H,"Playoff",'Game History'!I:I,Instructions!A69)+COUNTIFS('Game History'!A:A,(">"&(TODAY()-548)),'Game History'!G:G,"WFTDA",'Game History'!H:H,"Champs",'Game History'!I:I,Instructions!A70)+COUNTIFS('Game History'!A:A,(">"&(TODAY()-548)),'Game History'!G:G,"WFTDA",'Game History'!H:H,"Playoff",'Game History'!I:I,Instructions!A70) -> 0 | J6: =COUNTIFS('Game History'!A:A,(">"&(TODAY()-548)),'Game History'!G:G,"WFTDA",'Game History'!H:H,"Sanc",'Game History'!I:I,Instructions!A69) -> 0 | K6: =COUNTIFS('Game History'!A:A,(">"&(TODAY()-548)),'Game History'!G:G,"WFTDA",'Game History'!H:H,"Reg",'Game History'!I:I,Instructions!A69) -> 0 | L6: =SUM(I6,J6,K6) -> 0
A7: HR | B7: — | C7: =COUNTIFS('Game History'!A:A,(">"&(TODAY()-365)),'Game History'!G:G,"WFTDA",'Game History'!H:H,"Sanc",'Game History'!I:I,Instructions!A70) -> 0 | D7: =COUNTIFS('Game History'!A:A,(">"&(TODAY()-365)),'Game History'!G:G,"WFTDA",'Game History'!H:H,"Reg",'Game History'!I:I,Instructions!A70) -> 0 | E7: =SUM(C7+D7) -> 0 | H7: HR | I7: — | J7: =COUNTIFS('Game History'!A:A,(">"&(TODAY()-548)),'Game History'!G:G,"WFTDA",'Game History'!H:H,"Sanc",'Game History'!I:I,Instructions!A70) -> 0 | K7: =COUNTIFS('Game History'!A:A,(">"&(TODAY()-548)),'Game History'!G:G,"WFTDA",'Game History'!H:H,"Reg",'Game History'!I:I,Instructions!A70) -> 0 | L7: =SUM(J7+K7) -> 0
A8: JR | B8: =COUNTIFS('Game History'!A:A,(">"&(TODAY()-365)),'Game History'!G:G,"WFTDA",'Game History'!H:H,"Champs",'Game History'!I:I,Instructions!A74)+COUNTIFS('Game History'!A:A,(">"&(TODAY()-365)),'Game History'!G:G,"WFTDA",'Game History'!H:H,"Playoff",'Game History'!I:I,Instructions!A74)+COUNTIFS('Game History'!A:A,(">"&(TODAY()-365)),'Game History'!G:G,"WFTDA",'Game History'!H:H,"Champs",'Game History'!J:J,Instructions!A74)+COUNTIFS('Game History'!A:A,(">"&(TODAY()-365)),'Game History'!G:G,"WFTDA",'Game History'!H:H,"Playoff",'Game History'!J:J,Instructions!A74) -> 0 | C8: =COUNTIFS('Game History'!A:A,(">"&(TODAY()-365)),'Game History'!G:G,"WFTDA",'Game History'!H:H,"Sanc",'Game History'!I:I,Instructions!A74)+COUNTIFS('Game History'!A:A,(">"&(TODAY()-365)),'Game History'!G:G,"WFTDA",'Game History'!H:H,"Sanc",'Game History'!J:J,Instructions!A74) -> 0 | D8: =COUNTIFS('Game History'!A:A,(">"&(TODAY()-365)),'Game History'!G:G,"WFTDA",'Game History'!H:H,"Reg",'Game History'!I:I,Instructions!A74)+COUNTIFS('Game History'!A:A,(">"&(TODAY()-365)),'Game History'!G:G,"WFTDA",'Game History'!H:H,"Reg",'Game History'!J:J,Instructions!A74) -> 2 | E8: =SUM(B8,C8,D8) -> 2 | H8: JR | I8: =COUNTIFS('Game History'!A:A,(">"&(TODAY()-548)),'Game History'!G:G,"WFTDA",'Game History'!H:H,"Champs",'Game History'!I:I,Instructions!A74)+COUNTIFS('Game History'!A:A,(">"&(TODAY()-548)),'Game History'!G:G,"WFTDA",'Game History'!H:H,"Playoff",'Game History'!I:I,Instructions!A74)+COUNTIFS('Game History'!A:A,(">"&(TODAY()-548)),'Game History'!G:G,"WFTDA",'Game History'!H:H,"Champs",'Game History'!J:J,Instructions!A74)+COUNTIFS('Game History'!A:A,(">"&(TODAY()-548)),'Game History'!G:G,"WFTDA",'Game History'!H:H,"Playoff",'Game History'!J:J,Instructions!A74) -> 0 | J8: =COUNTIFS('Game History'!A:A,(">"&(TODAY()-548)),'Game History'!G:G,"WFTDA",'Game History'!H:H,"Sanc",'Game History'!I:I,Instructions!A74)+COUNTIFS('Game History'!A:A,(">"&(TODAY()-548)),'Game History'!G:G,"WFTDA",'Game History'!H:H,"Sanc",'Game History'!J:J,Instructions!A74) -> 0 | K8: =COUNTIFS('Game History'!A:A,(">"&(TODAY()-548)),'Game History'!G:G,"WFTDA",'Game History'!H:H,"Reg",'Game History'!I:I,Instructions!A74)+COUNTIFS('Game History'!A:A,(">"&(TODAY()-548)),'Game History'!G:G,"WFTDA",'Game History'!H:H,"Reg",'Game History'!J:J,Instructions!A74) -> 2 | L8: =SUM(I8,J8,K8) -> 2
A9: IPR | B9: =COUNTIFS('Game History'!A:A,(">"&(TODAY()-365)),'Game History'!G:G,"WFTDA",'Game History'!H:H,"Champs",'Game History'!I:I,Instructions!A75)+COUNTIFS('Game History'!A:A,(">"&(TODAY()-365)),'Game History'!G:G,"WFTDA",'Game History'!H:H,"Playoff",'Game History'!I:I,Instructions!A75)+COUNTIFS('Game History'!A:A,(">"&(TODAY()-365)),'Game History'!G:G,"WFTDA",'Game History'!H:H,"Champs",'Game History'!J:J,Instructions!A75)+COUNTIFS('Game History'!A:A,(">"&(TODAY()-365)),'Game History'!G:G,"WFTDA",'Game History'!H:H,"Playoff",'Game History'!J:J,Instructions!A75) -> 0 | C9: =COUNTIFS('Game History'!A:A,(">"&(TODAY()-365)),'Game History'!G:G,"WFTDA",'Game History'!H:H,"Sanc",'Game History'!I:I,Instructions!A75)+COUNTIFS('Game History'!A:A,(">"&(TODAY()-365)),'Game History'!G:G,"WFTDA",'Game History'!H:H,"Sanc",'Game History'!J:J,Instructions!A75) -> 0 | D9: =COUNTIFS('Game History'!A:A,(">"&(TODAY()-365)),'Game History'!G:G,"WFTDA",'Game History'!H:H,"Reg",'Game History'!I:I,Instructions!A75)+COUNTIFS('Game History'!A:A,(">"&(TODAY()-365)),'Game History'!G:G,"WFTDA",'Game History'!H:H,"Reg",'Game History'!J:J,Instructions!A75) -> 1 | E9: =SUM(B9,C9,D9) -> 1 | H9: IPR | I9: =COUNTIFS('Game History'!A:A,(">"&(TODAY()-548)),'Game History'!G:G,"WFTDA",'Game History'!H:H,"Champs",'Game History'!I:I,Instructions!A75)+COUNTIFS('Game History'!A:A,(">"&(TODAY()-548)),'Game History'!G:G,"WFTDA",'Game History'!H:H,"Playoff",'Game History'!I:I,Instructions!A75)+COUNTIFS('Game History'!A:A,(">"&(TODAY()-548)),'Game History'!G:G,"WFTDA",'Game History'!H:H,"Champs",'Game History'!J:J,Instructions!A75)+COUNTIFS('Game History'!A:A,(">"&(TODAY()-548)),'Game History'!G:G,"WFTDA",'Game History'!H:H,"Playoff",'Game History'!J:J,Instructions!A75) -> 0 | J9: =COUNTIFS('Game History'!A:A,(">"&(TODAY()-548)),'Game History'!G:G,"WFTDA",'Game History'!H:H,"Sanc",'Game History'!I:I,Instructions!A75)+COUNTIFS('Game History'!A:A,(">"&(TODAY()-548)),'Game History'!G:G,"WFTDA",'Game History'!H:H,"Sanc",'Game History'!J:J,Instructions!A75) -> 0 | K9: =COUNTIFS('Game History'!A:A,(">"&(TODAY()-548)),'Game History'!G:G,"WFTDA",'Game History'!H:H,"Reg",'Game History'!I:I,Instructions!A75)+COUNTIFS('Game History'!A:A,(">"&(TODAY()-548)),'Game History'!G:G,"WFTDA",'Game History'!H:H,"Reg",'Game History'!J:J,Instructions!A75) -> 1 | L9: =SUM(I9,J9,K9) -> 1
A10: OPR | B10: =COUNTIFS('Game History'!A:A,(">"&(TODAY()-365)),'Game History'!G:G,"WFTDA",'Game History'!H:H,"Champs",'Game History'!I:I,Instructions!A76)+COUNTIFS('Game History'!A:A,(">"&(TODAY()-365)),'Game History'!G:G,"WFTDA",'Game History'!H:H,"Playoff",'Game History'!I:I,Instructions!A76)+COUNTIFS('Game History'!A:A,(">"&(TODAY()-365)),'Game History'!G:G,"WFTDA",'Game History'!H:H,"Champs",'Game History'!J:J,Instructions!A76)+COUNTIFS('Game History'!A:A,(">"&(TODAY()-365)),'Game History'!G:G,"WFTDA",'Game History'!H:H,"Playoff",'Game History'!J:J,Instructions!A76) -> 0 | C10: =COUNTIFS('Game History'!A:A,(">"&(TODAY()-365)),'Game History'!G:G,"WFTDA",'Game History'!H:H,"Sanc",'Game History'!I:I,Instructions!A76)+COUNTIFS('Game History'!A:A,(">"&(TODAY()-365)),'Game History'!G:G,"WFTDA",'Game History'!H:H,"Sanc",'Game History'!J:J,Instructions!A76) -> 0 | D10: =COUNTIFS('Game History'!A:A,(">"&(TODAY()-365)),'Game History'!G:G,"WFTDA",'Game History'!H:H,"Reg",'Game History'!I:I,Instructions!A76)+COUNTIFS('Game History'!A:A,(">"&(TODAY()-365)),'Game History'!G:G,"WFTDA",'Game History'!H:H,"Reg",'Game History'!J:J,Instructions!A76) -> 4 | E10: =SUM(B10,C10,D10) -> 4 | H10: OPR | I10: =COUNTIFS('Game History'!A:A,(">"&(TODAY()-548)),'Game History'!G:G,"WFTDA",'Game History'!H:H,"Champs",'Game History'!I:I,Instructions!A76)+COUNTIFS('Game History'!A:A,(">"&(TODAY()-548)),'Game History'!G:G,"WFTDA",'Game History'!H:H,"Playoff",'Game History'!I:I,Instructions!A76)+COUNTIFS('Game History'!A:A,(">"&(TODAY()-548)),'Game History'!G:G,"WFTDA",'Game History'!H:H,"Champs",'Game History'!J:J,Instructions!A76)+COUNTIFS('Game History'!A:A,(">"&(TODAY()-548)),'Game History'!G:G,"WFTDA",'Game History'!H:H,"Playoff",'Game History'!J:J,Instructions!A76) -> 0 | J10: =COUNTIFS('Game History'!A:A,(">"&(TODAY()-548)),'Game History'!G:G,"WFTDA",'Game History'!H:H,"Sanc",'Game History'!I:I,Instructions!A76)+COUNTIFS('Game History'!A:A,(">"&(TODAY()-548)),'Game History'!G:G,"WFTDA",'Game History'!H:H,"Sanc",'Game History'!J:J,Instructions!A76) -> 0 | K10: =COUNTIFS('Game History'!A:A,(">"&(TODAY()-548)),'Game History'!G:G,"WFTDA",'Game History'!H:H,"Reg",'Game History'!I:I,Instructions!A76)+COUNTIFS('Game History'!A:A,(">"&(TODAY()-548)),'Game History'!G:G,"WFTDA",'Game History'!H:H,"Reg",'Game History'!J:J,Instructions!A76) -> 4 | L10: =SUM(I10,J10,K10) -> 4
A11: ALT | B11: =COUNTIFS('Game History'!A:A,(">"&(TODAY()-365)),'Game History'!G:G,"WFTDA",'Game History'!H:H,"Champs",'Game History'!I:I,Instructions!A87)+COUNTIFS('Game History'!A:A,(">"&(TODAY()-365)),'Game History'!G:G,"WFTDA",'Game History'!H:H,"Playoff",'Game History'!I:I,Instructions!A87) -> 0 | C11: =COUNTIFS('Game History'!A:A,(">"&(TODAY()-365)),'Game History'!G:G,"WFTDA",'Game History'!H:H,"Sanc",'Game History'!I:I,Instructions!A87) -> 0 | D11: =COUNTIFS('Game History'!A:A,(">"&(TODAY()-365)),'Game History'!G:G,"WFTDA",'Game History'!H:H,"Reg",'Game History'!I:I,Instructions!A87) -> 0 | E11: =SUM(B11,C11,D11) -> 0 | H11: ALT | I11: =COUNTIFS('Game History'!A:A,(">"&(TODAY()-548)),'Game History'!G:G,"WFTDA",'Game History'!H:H,"Champs",'Game History'!I:I,Instructions!A87)+COUNTIFS('Game History'!A:A,(">"&(TODAY()-548)),'Game History'!G:G,"WFTDA",'Game History'!H:H,"Playoff",'Game History'!I:I,Instructions!A87) -> 0 | J11: =COUNTIFS('Game History'!A:A,(">"&(TODAY()-548)),'Game History'!G:G,"WFTDA",'Game History'!H:H,"Sanc",'Game History'!I:I,Instructions!A87) -> 0 | K11: =COUNTIFS('Game History'!A:A,(">"&(TODAY()-548)),'Game History'!G:G,"WFTDA",'Game History'!H:H,"Reg",'Game History'!I:I,Instructions!A87) -> 0 | L11: =SUM(I11,J11,K11) -> 0
A12: Total* | B12: =SUM(B5:B11) -> 0 | C12: =SUM(C5:C11) -> 0 | D12: =SUM(D5:D11) -> 7 | E12: =SUM(E5:E11) -> 7 | H12: Total* | I12: =SUM(I5:I11) -> 0 | J12: =SUM(J5:J11) -> 0 | K12: =SUM(K5:K11) -> 7 | L12: =SUM(L5:L11) -> 7
A15: WFTDA Non-Skating Official
A17: 1 YEAR | B17: Playoff | C17: Sanc | D17: Reg | E17: Total | H17: 18 MONTHS | I17: Playoff | J17: Sanc | K17: Reg | L17: Total
