Workbook

Sheet Instructions
A1: =IFERROR(__xludf.dummyfunction("IMPORTRANGE(""1V5OIElI2MQo07KSlDqNMWMvWuTLDbyT-YC4EEx4A3Gw"", ""Live Instructions!A1:K123"")"),"#REF!") -> #REF! | J1: ="COMPUTED_VALUE" -> COMPUTED_VALUE | K1: ="COMPUTED_VALUE" -> COMPUTED_VALUE
A2: ="COMPUTED_VALUE" -> COMPUTED_VALUE
A4: ="COMPUTED_VALUE" -> COMPUTED_VALUE
A5: ="COMPUTED_VALUE" -> COMPUTED_VALUE | F5: ="COMPUTED_VALUE" -> COMPUTED_VALUE | I5: ="COMPUTED_VALUE" -> COMPUTED_VALUE
A6: ="COMPUTED_VALUE" -> COMPUTED_VALUE | E6: ="COMPUTED_VALUE" -> COMPUTED_VALUE
A8: ="COMPUTED_VALUE" -> COMPUTED_VALUE
A9: ="COMPUTED_VALUE" -> COMPUTED_VALUE
A10: ="COMPUTED_VALUE" -> COMPUTED_VALUE
A12: ="COMPUTED_VALUE" -> COMPUTED_VALUE
A13: ="COMPUTED_VALUE" -> COMPUTED_VALUE
A14: ="COMPUTED_VALUE" -> COMPUTED_VALUE
A15: ="COMPUTED_VALUE" -> COMPUTED_VALUE
A16: ="COMPUTED_VALUE" -> COMPUTED_VALUE
A17: ="COMPUTED_VALUE" -> COMPUTED_VALUE
A19: ="COMPUTED_VALUE" -> COMPUTED_VALUE
A20: ="COMPUTED_VALUE" -> COMPUTED_VALUE
A21: ="COMPUTED_VALUE" -> COMPUTED_VALUE
A22: ="COMPUTED_VALUE" -> COMPUTED_VALUE
B23: ="COMPUTED_VALUE" -> COMPUTED_VALUE
A24: ="COMPUTED_VALUE" -> COMPUTED_VALUE
A26: ="COMPUTED_VALUE" -> COMPUTED_VALUE
A27: ="COMPUTED_VALUE" -> COMPUTED_VALUE
A28: ="COMPUTED_VALUE" -> COMPUTED_VALUE
A29: ="COMPUTED_VALUE" -> COMPUTED_VALUE
B30: ="COMPUTED_VALUE" -> COMPUTED_VALUE
A31: ="COMPUTED_VALUE" -> COMPUTED_VALUE
B32: ="COMPUTED_VALUE" -> COMPUTED_VALUE
A34: ="COMPUTED_VALUE" -> COMPUTED_VALUE
A35: ="COMPUTED_VALUE" -> COMPUTED_VALUE
A36: ="COMPUTED_VALUE" -> COMPUTED_VALUE
A37: ="COMPUTED_VALUE" -> COMPUTED_VALUE
B38: ="COMPUTED_VALUE" -> COMPUTED_VALUE
B39: ="COMPUTED_VALUE" -> COMPUTED_VALUE
B40: ="COMPUTED_VALUE" -> COMPUTED_VALUE
A41: ="COMPUTED_VALUE" -> COMPUTED_VALUE
B42: ="COMPUTED_VALUE" -> COMPUTED_VALUE
A43: ="COMPUTED_VALUE" -> COMPUTED_VALUE
A44: ="COMPUTED_VALUE" -> COMPUTED_VALUE
A45: ="COMPUTED_VALUE" -> COMPUTED_VALUE | K45: ="COMPUTED_VALUE" -> COMPUTED_VALUE
A47: ="COMPUTED_VALUE" -> COMPUTED_VALUE
...

Sheet Summary
A1: Flat Track Derby Game History Summary | L1: =image("http://wftda.com/wftda-logo.png", 4, 50, 50) -> #NAME? | N1: =image("http://wftda.com/mrda.jpg", 4, 50, 34) -> #NAME?
A3: Official's Legal Name | C3: Alan Robertson | I3: Today's Date | J3: =TODAY() -> 46200
A4: Official's Derby Name | C4: Redacted | I4: Officiating Since | J4: 44807
A5: Affiliated League | C5: Sydney Roller Derby League
A6: Insurance # | F6: Provider | H6: Skate Victoria
A7: Ref Cert Level | E7: Endorsement(s)
A8: NSO Cert Level | E8: Endorsement(s)
A10: WFTDA
A11: Skating Positions | C11: Code | D11: Game Designation | I11: Non-Skating Positions | J11: Code | K11: Game Designation
D12: Playoff | E12: Sanc | F12: Reg | G12: Other | K12: Playoff | L12: Sanc | M12: Reg | N12: Other
A13: Head Referee | C13: HR | D13: — | E13: =COUNTIFS('Game History'!$G:$G,"WFTDA",'Game History'!$H:$H,"Sanc", 'Game History'!$I:$I,$C13) -> 0 | F13: =COUNTIFS('Game History'!$G:$G,"WFTDA",'Game History'!$H:$H,"Reg", 'Game History'!$I:$I,$C13) -> 0 | G13: =COUNTIFS('Game History'!$G:$G,"WFTDA",'Game History'!$H:$H,"Other", 'Game History'!$I:$I,$C13) -> 0 | I13: Head NSO | J13: HNSO | K13: — | L13: =COUNTIFS('Game History'!$G:$G,"WFTDA",'Game History'!$H:$H,"Sanc", 'Game History'!$I:$I,$J13) -> 0 | M13: =COUNTIFS('Game History'!$G:$G,"WFTDA",'Game History'!$H:$H,"Reg", 'Game History'!$I:$I,$J13) -> 0 | N13: =COUNTIFS('Game History'!$G:$G,"WFTDA",'Game History'!$H:$H,"Other", 'Game History'!$I:$I,$J13) -> 0
A14: Jammer Referee | C14: JR | D14: =COUNTIFS('Game History'!$G:$G,"WFTDA",'Game History'!$H:$H,"Playoff", 'Game History'!$I:$I,$C14) -> 0 | E14: =COUNTIFS('Game History'!$G:$G,"WFTDA",'Game History'!$H:$H,"Sanc", 'Game History'!$I:$I,$C14) -> 2 | F14: =COUNTIFS('Game History'!$G:$G,"WFTDA",'Game History'!$H:$H,"Reg", 'Game History'!$I:$I,$C14) -> 5 | G14: =COUNTIFS('Game History'!$G:$G,"WFTDA",'Game History'!$H:$H,"Other", 'Game History'!$I:$I,$C14) -> 4 | I14: Penalty Tracker | J14: PT | K14: =COUNTIFS('Game History'!$G:$G,"WFTDA",'Game History'!$H:$H,"Playoff", 'Game History'!$I:$I,$J14) -> 0 | L14: =COUNTIFS('Game History'!$G:$G,"WFTDA",'Game History'!$H:$H,"Sanc", 'Game History'!$I:$I,$J14) -> 0 | M14: =COUNTIFS('Game History'!$G:$G,"WFTDA",'Game History'!$H:$H,"Reg", 'Game History'!$I:$I,$J14) -> 2 | N14: =COUNTIFS('Game History'!$G:$G,"WFTDA",'Game History'!$H:$H,"Other", 'Game History'!$I:$I,$J14) -> 2
A15: Inside Pack Referee | C15: IPR | D15: =COUNTIFS('Game History'!$G:$G,"WFTDA",'Game History'!$H:$H,"Playoff", 'Game History'!$I:$I,$C15) -> 0 | E15: =COUNTIFS('Game History'!$G:$G,"WFTDA",'Game History'!$H:$H,"Sanc", 'Game History'!$I:$I,$C15) -> 0 | F15: =COUNTIFS('Game History'!$G:$G,"WFTDA",'Game History'!$H:$H,"Reg", 'Game History'!$I:$I,$C15) -> 0 | G15: =COUNTIFS('Game History'!$G:$G,"WFTDA",'Game History'!$H:$H,"Other", 'Game History'!$I:$I,$C15) -> 1 | I15: Penalty Wrangler | J15: PW | K15: =COUNTIFS('Game History'!$G:$G,"WFTDA",'Game History'!$H:$H,"Playoff", 'Game History'!$I:$I,$J15) -> 0 | L15: =COUNTIFS('Game History'!$G:$G,"WFTDA",'Game History'!$H:$H,"Sanc", 'Game History'!$I:$I,$J15) -> 0 | M15: =COUNTIFS('Game History'!$G:$G,"WFTDA",'Game History'!$H:$H,"Reg", 'Game History'!$I:$I,$J15) -> 0 | N15: =COUNTIFS('Game History'!$G:$G,"WFTDA",'Game History'!$H:$H,"Other", 'Game History'!$I:$I,$J15) -> 0
A16: Outside Pack Referee | C16: OPR | D16: =COUNTIFS('Game History'!$G:$G,"WFTDA",'Game History'!$H:$H,"Playoff", 'Game History'!$I:$I,$C16) -> 2 | E16: =COUNTIFS('Game History'!$G:$G,"WFTDA",'Game History'!$H:$H,"Sanc", 'Game History'!$I:$I,$C16) -> 5 | F16: =COUNTIFS('Game History'!$G:$G,"WFTDA",'Game History'!$H:$H,"Reg", 'Game History'!$I:$I,$C16) -> 16 | G16: =COUNTIFS('Game History'!$G:$G,"WFTDA",'Game History'!$H:$H,"Other", 'Game History'!$I:$I,$C16) -> 4 | I16: Inside White Board | J16: IWB | K16: =COUNTIFS('Game History'!$G:$G,"WFTDA",'Game History'!$H:$H,"Playoff", 'Game History'!$I:$I,$J16) -> 0 | L16: =COUNTIFS('Game History'!$G:$G,"WFTDA",'Game History'!$H:$H,"Sanc", 'Game History'!$I:$I,$J16) -> 0 | M16: =COUNTIFS('Game History'!$G:$G,"WFTDA",'Game History'!$H:$H,"Reg", 'Game History'!$I:$I,$J16) -> 0 | N16: =COUNTIFS('Game History'!$G:$G,"WFTDA",'Game History'!$H:$H,"Other", 'Game History'!$I:$I,$J16) -> 0
A17: Alternate Referee | C17: ALTR | D17: =COUNTIFS('Game History'!$G:$G,"WFTDA",'Game History'!$H:$H,"Playoff", 'Game History'!$I:$I,$C17) -> 0 | E17: =COUNTIFS('Game History'!$G:$G,"WFTDA",'Game History'!$H:$H,"Sanc", 'Game History'!$I:$I,$C17) -> 0 | F17: =COUNTIFS('Game History'!$G:$G,"WFTDA",'Game History'!$H:$H,"Reg", 'Game History'!$I:$I,$C17) -> 1 | G17: =COUNTIFS('Game History'!$G:$G,"WFTDA",'Game History'!$H:$H,"Other", 'Game History'!$I:$I,$C17) -> 1 | I17: Outside White Board | J17: OWB | K17: =COUNTIFS('Game History'!$G:$G,"WFTDA",'Game History'!$H:$H,"Playoff", 'Game History'!$I:$I,$J17) -> 0 | L17: =COUNTIFS('Game History'!$G:$G,"WFTDA",'Game History'!$H:$H,"Sanc", 'Game History'!$I:$I,$J17) -> 0 | M17: =COUNTIFS('Game History'!$G:$G,"WFTDA",'Game History'!$H:$H,"Reg", 'Game History'!$I:$I,$J17) -> 0 | N17: =COUNTIFS('Game History'!$G:$G,"WFTDA",'Game History'!$H:$H,"Other", 'Game History'!$I:$I,$J17) -> 0
A18: Total Referee | D18: =SUM(D14:D17) -> 2 | E18: =SUM(E13:E17) -> 7 | F18: =SUM(F13:F17) -> 22 | G18: =SUM(G13:G17) -> 10 | I18: Jam Timer | J18: JT | K18: =COUNTIFS('Game History'!$G:$G,"WFTDA",'Game History'!$H:$H,"Playoff", 'Game History'!$I:$I,$J18) -> 0 | L18: =COUNTIFS('Game History'!$G:$G,"WFTDA",'Game History'!$H:$H,"Sanc", 'Game History'!$I:$I,$J18) -> 0 | M18: =COUNTIFS('Game History'!$G:$G,"WFTDA",'Game History'!$H:$H,"Reg", 'Game History'!$I:$I,$J18) -> 5 | N18: =COUNTIFS('Game History'!$G:$G,"WFTDA",'Game History'!$H:$H,"Other", 'Game History'!$I:$I,$J18) -> 0
I19: Scorekeeper | J19: SK | K19: =COUNTIFS('Game History'!$G:$G,"WFTDA",'Game History'!$H:$H,"Playoff", 'Game History'!$I:$I,$J19) -> 0 | L19: =COUNTIFS('Game History'!$G:$G,"WFTDA",'Game History'!$H:$H,"Sanc", 'Game History'!$I:$I,$J19) -> 1 | M19: =COUNTIFS('Game History'!$G:$G,"WFTDA",'Game History'!$H:$H,"Reg", 'Game History'!$I:$I,$J19) -> 4 | N19: =COUNTIFS('Game History'!$G:$G,"WFTDA",'Game History'!$H:$H,"Other", 'Game History'!$I:$I,$J19) -> 2
A20: Tournament Head Referee | C20: THR | D20: =COUNTIFS('Game History'!G:G,"WFTDA",'Game History'!H:H,"Champs",'Game History'!I:I,Instructions!A68)+COUNTIFS('Game History'!G:G,"WFTDA",'Game History'!H:H,"Playoff",'Game History'!I:I,Instructions!A68) -> 0 | E20: =COUNTIFS('Game History'!G:G,"WFTDA",'Game History'!H:H,"Sanc",'Game History'!I:I,Instructions!A68) -> 0 | F20: =COUNTIFS('Game History'!G:G,"WFTDA",'Game History'!H:H,"Reg",'Game History'!I:I,Instructions!A68) -> 0 | G20: =COUNTIFS('Game History'!G:G,"WFTDA",'Game History'!H:H,"Other",'Game History'!I:I,Instructions!A68) -> 0 | I20: Scoreboard Operator | J20: SO | K20: =COUNTIFS('Game History'!$G:$G,"WFTDA",'Game History'!$H:$H,"Playoff", 'Game History'!$I:$I,$J20) -> 2 | L20: =COUNTIFS('Game History'!$G:$G,"WFTDA",'Game History'!$H:$H,"Sanc", 'Game History'!$I:$I,$J20) -> 1 | M20: =COUNTIFS('Game History'!$G:$G,"WFTDA",'Game History'!$H:$H,"Reg", 'Game History'!$I:$I,$J20) -> 7 | N20: =COUNTIFS('Game History'!$G:$G,"WFTDA",'Game History'!$H:$H,"Other", 'Game History'!$I:$I,$J20) -> 2
A21: Crew Head Referee | C21: CHR | D21: =COUNTIFS('Game History'!G:G,"WFTDA",'Game History'!H:H,"Champs",'Game History'!I:I,Instructions!A69)+COUNTIFS('Game History'!G:G,"WFTDA",'Game History'!H:H,"Playoff",'Game History'!I:I,Instructions!A69)+COUNTIFS('Game History'!G:G,"WFTDA",'Game History'!H:H,"Champs",'Game History'!I:I,Instructions!A70)+COUNTIFS('Game History'!G:G,"WFTDA",'Game History'!H:H,"Playoff",'Game History'!I:I,Instructions!A70) -> 0 | E21: =COUNTIFS('Game History'!G:G,"WFTDA",'Game History'!H:H,"Sanc",'Game History'!I:I,Instructions!A69) -> 0 | F21: =COUNTIFS('Game History'!G:G,"WFTDA",'Game History'!H:H,"Reg",'Game History'!I:I,Instructions!A69) -> 0 | G21: =COUNTIFS('Game History'!G:G,"WFTDA",'Game History'!H:H,"Other",'Game History'!I:I,Instructions!A69) -> 0 | I21: Penalty Box Manager | J21: PBM | K21: =COUNTIFS('Game History'!$G:$G,"WFTDA",'Game History'!$H:$H,"Playoff", 'Game History'!$I:$I,$J21) -> 0 | L21: =COUNTIFS('Game History'!$G:$G,"WFTDA",'Game History'!$H:$H,"Sanc", 'Game History'!$I:$I,$J21) -> 0 | M21: =COUNTIFS('Game History'!$G:$G,"WFTDA",'Game History'!$H:$H,"Reg", 'Game History'!$I:$I,$J21) -> 3 | N21: =COUNTIFS('Game History'!$G:$G,"WFTDA",'Game History'!$H:$H,"Other", 'Game History'!$I:$I,$J21) -> 0
A22: Games Official | C22: GO | D22: =COUNTIFS('Game History'!G:G,"WFTDA",'Game History'!H:H,"Champs",'Game History'!I:I,Instructions!A67)+COUNTIFS('Game History'!G:G,"WFTDA",'Game History'!H:H,"Playoff",'Game History'!I:I,Instructions!A67) -> 0 | E22: =COUNTIFS('Game History'!G:G,"WFTDA",'Game History'!H:H,"Sanc",'Game History'!I:I,Instructions!A67) -> 0 | F22: =COUNTIFS('Game History'!G:G,"WFTDA",'Game History'!H:H,"Reg",'Game History'!I:I,Instructions!A67) -> 0 | G22: =COUNTIFS('Game History'!G:G,"WFTDA",'Game History'!H:H,"Other",'Game History'!I:I,Instructions!A67) -> 0 | I22: Penalty Box Timer | J22: PBT | K22: =COUNTIFS('Game History'!$G:$G,"WFTDA",'Game History'!$H:$H,"Playoff", 'Game History'!$I:$I,$J22) -> 0 | L22: =COUNTIFS('Game History'!$G:$G,"WFTDA",'Game History'!$H:$H,"Sanc", 'Game History'!$I:$I,$J22) -> 0 | M22: =COUNTIFS('Game History'!$G:$G,"WFTDA",'Game History'!$H:$H,"Reg", 'Game History'!$I:$I,$J22) -> 10 | N22: =COUNTIFS('Game History'!$G:$G,"WFTDA",'Game History'!$H:$H,"Other", 'Game History'!$I:$I,$J22) -> 1
A23: Tournament Head NSO | C23: THNSO | D23: =COUNTIFS('Game History'!G:G,"WFTDA",'Game History'!H:H,"Champs",'Game History'!I:I,Instructions!A71)+COUNTIFS('Game History'!G:G,"WFTDA",'Game History'!H:H,"Playoff",'Game History'!I:I,Instructions!A71) -> 0 | E23: =COUNTIFS('Game History'!G:G,"WFTDA",'Game History'!H:H,"Sanc",'Game History'!I:I,Instructions!A71) -> 0 | F23: =COUNTIFS('Game History'!G:G,"WFTDA",'Game History'!H:H,"Reg",'Game History'!I:I,Instructions!A71) -> 0 | G23: =COUNTIFS('Game History'!G:G,"WFTDA",'Game History'!H:H,"Other",'Game History'!I:I,Instructions!A71) -> 0 | I23: Lineup Tracker | J23: LT | K23: =COUNTIFS('Game History'!$G:$G,"WFTDA",'Game History'!$H:$H,"Playoff", 'Game History'!$I:$I,$J23) -> 0 | L23: =COUNTIFS('Game History'!$G:$G,"WFTDA",'Game History'!$H:$H,"Sanc", 'Game History'!$I:$I,$J23) -> 0 | M23: =COUNTIFS('Game History'!$G:$G,"WFTDA",'Game History'!$H:$H,"Reg", 'Game History'!$I:$I,$J23) -> 1 | N23: =COUNTIFS('Game History'!$G:$G,"WFTDA",'Game History'!$H:$H,"Other", 'Game History'!$I:$I,$J23) -> 0
A24: Crew Head NSO | C24: CHNSO | D24: =COUNTIFS('Game History'!G:G,"WFTDA",'Game History'!H:H,"Champs",'Game History'!I:I,Instructions!A72)+COUNTIFS('Game History'!G:G,"WFTDA",'Game History'!H:H,"Playoff",'Game History'!I:I,Instructions!A72)+COUNTIFS('Game History'!G:G,"WFTDA",'Game History'!H:H,"Champs",'Game History'!I:I,Instructions!A73)+COUNTIFS('Game History'!G:G,"WFTDA",'Game History'!H:H,"Playoff",'Game History'!I:I,Instructions!A73) -> 0 | E24: =COUNTIFS('Game History'!G:G,"WFTDA",'Game History'!H:H,"Sanc",'Game History'!I:I,Instructions!A72) -> 0 | F24: =COUNTIFS('Game History'!G:G,"WFTDA",'Game History'!H:H,"Reg",'Game History'!I:I,Instructions!A72) -> 0 | G24: =COUNTIFS('Game History'!G:G,"WFTDA",'Game History'!H:H,"Other",'Game History'!I:I,Instructions!A72) -> 0 | I24: Alternate NSO | J24: ALTN | K24: =COUNTIFS('Game History'!$G:$G,"WFTDA",'Game History'!$H:$H,"Playoff", 'Game History'!$I:$I,$J24) -> 0 | L24: =COUNTIFS('Game History'!$G:$G,"WFTDA",'Game History'!$H:$H,"Sanc", 'Game History'!$I:$I,$J24) -> 0 | M24: =COUNTIFS('Game History'!$G:$G,"WFTDA",'Game History'!$H:$H,"Reg", 'Game History'!$I:$I,$J24) -> 0 | N24: =COUNTIFS('Game History'!$G:$G,"WFTDA",'Game History'!$H:$H,"Other", 'Game History'!$I:$I,$J24) -> 0
I25: Total NSO | K25: =SUM(K14:K24) -> 2 | L25: =SUM(L13:L24) -> 2 | M25: =SUM(M13:M24) -> 32 | N25: =SUM(N13:N24) -> 7
A26: WFTDA Officiating Clinics attended | I26: Total Software Operator Game Experience | M26: =COUNTIFS('Game History'!G:G,"WFTDA",'Game History'!K:K,"Y") -> 0
A27: REF or NSO Track | B27: Location | C27: Year | D27: REF or NSO Track | E27: Location | G27: Year
I28: WFTDA Games Totals | K28: Current Rule Set | M28: Lifetime
K29: Referee | L29: NSO | M29: Referee | N29: NSO
K30: =SUM(D18:F18) -> 31 | L30: =SUM(K25:M25) -> 36 | M30: =SUM(D18:G18) -> 41 | N30: =SUM(K25:N25) -> 43
A33: MRDA
A34: Skating Positions | C34: Code | D34: Game Designation | I34: Non-Skating Positions | J34: Code | K34: Game Designation
D35: Playoff | E35: Sanc | F35: Reg | G35: Other | K35: Playoff | L35: Sanc | M35: Reg | N35: Other
A36: Head Referee | C36: HR | D36: — | E36: =COUNTIFS('Game History'!G:G,"MRDA",'Game History'!H:H,"Sanc",'Game History'!I:I,Instructions!A70) -> 0 | F36: =COUNTIFS('Game History'!G:G,"MRDA",'Game History'!H:H,"Reg",'Game History'!I:I,Instructions!A70) -> 0 | G36: =COUNTIFS('Game History'!G:G,"MRDA",'Game History'!H:H,"Other",'Game History'!I:I,Instructions!A70) -> 0 | I36: Head NSO | J36: HNSO | K36: — | L36: =COUNTIFS('Game History'!G:G,"MRDA",'Game History'!H:H,"Sanc",'Game History'!I:I,Instructions!A73) -> 0 | M36: =COUNTIFS('Game History'!G:G,"MRDA",'Game History'!H:H,"Reg",'Game History'!I:I,Instructions!A73) -> 0 | N36: =COUNTIFS('Game History'!G:G,"MRDA",'Game History'!H:H,"Other",'Game History'!I:I,Instructions!A73) -> 0
A37: Jammer Referee | C37: JR | D37: =COUNTIFS('Game History'!G:G,"MRDA",'Game History'!H:H,"Champs",'Game History'!I:I,Instructions!A74)+COUNTIFS('Game History'!G:G,"MRDA",'Game History'!H:H,"Playoff",'Game History'!I:I,Instructions!A74) -> 0 | E37: =COUNTIFS('Game History'!G:G,"MRDA",'Game History'!H:H,"Sanc",'Game History'!I:I,Instructions!A74) -> 0 | F37: =COUNTIFS('Game History'!G:G,"MRDA",'Game History'!H:H,"Reg",'Game History'!I:I,Instructions!A74) -> 0 | G37: =COUNTIFS('Game History'!G:G,"MRDA",'Game History'!H:H,"Other",'Game History'!I:I,Instructions!A74) -> 0 | I37: Penalty Tracker | J37: PT | K37: =COUNTIFS('Game History'!G:G,"MRDA",'Game History'!H:H,"Champs",'Game History'!I:I,Instructions!A77)+COUNTIFS('Game History'!G:G,"MRDA",'Game History'!H:H,"Playoff",'Game History'!I:I,Instructions!A77) -> 0 | L37: =COUNTIFS('Game History'!G:G,"MRDA",'Game History'!H:H,"Sanc",'Game History'!I:I,Instructions!A77) -> 0 | M37: =COUNTIFS('Game History'!G:G,"MRDA",'Game History'!H:H,"Reg",'Game History'!I:I,Instructions!A77) -> 0 | N37: =COUNTIFS('Game History'!G:G,"MRDA",'Game History'!H:H,"Other",'Game History'!I:I,Instructions!A77) -> 0
A38: Inside Pack Referee | C38: IPR | D38: =COUNTIFS('Game History'!G:G,"MRDA",'Game History'!H:H,"Champs",'Game History'!I:I,Instructions!A75)+COUNTIFS('Game History'!G:G,"MRDA",'Game History'!H:H,"Playoff",'Game History'!I:I,Instructions!A75) -> 0 | E38: =COUNTIFS('Game History'!G:G,"MRDA",'Game History'!H:H,"Sanc",'Game History'!I:I,Instructions!A75) -> 0 | F38: =COUNTIFS('Game History'!G:G,"MRDA",'Game History'!H:H,"Reg",'Game History'!I:I,Instructions!A75) -> 0 | G38: =COUNTIFS('Game History'!G:G,"MRDA",'Game History'!H:H,"Other",'Game History'!I:I,Instructions!A75) -> 0 | I38: Penalty Wrangler | J38: PW | K38: =COUNTIFS('Game History'!G:G,"MRDA",'Game History'!H:H,"Champs",'Game History'!I:I,Instructions!A78)+COUNTIFS('Game History'!G:G,"MRDA",'Game History'!H:H,"Playoff",'Game History'!I:I,Instructions!A78) -> 0 | L38: =COUNTIFS('Game History'!G:G,"MRDA",'Game History'!H:H,"Sanc",'Game History'!I:I,Instructions!A78) -> 0 | M38: =COUNTIFS('Game History'!G:G,"MRDA",'Game History'!H:H,"Reg",'Game History'!I:I,Instructions!A78) -> 0 | N38: =COUNTIFS('Game History'!G:G,"MRDA",'Game History'!H:H,"Other",'Game History'!I:I,Instructions!A78) -> 0
A39: Outside Pack Referee | C39: OPR | D39: =COUNTIFS('Game History'!G:G,"MRDA",'Game History'!H:H,"Champs",'Game History'!I:I,Instructions!A76)+COUNTIFS('Game History'!G:G,"MRDA",'Game History'!H:H,"Playoff",'Game History'!I:I,Instructions!A76) -> 0 | E39: =COUNTIFS('Game History'!G:G,"MRDA",'Game History'!H:H,"Sanc",'Game History'!I:I,Instructions!A76) -> 0 | F39: =COUNTIFS('Game History'!G:G,"MRDA",'Game History'!H:H,"Reg",'Game History'!I:I,Instructions!A76) -> 0 | G39: =COUNTIFS('Game History'!G:G,"MRDA",'Game History'!H:H,"Other",'Game History'!I:I,Instructions!A76) -> 0 | I39: Inside White Board | J39: IWB | K39: =COUNTIFS('Game History'!G:G,"MRDA",'Game History'!H:H,"Champs",'Game History'!I:I,Instructions!A79)+COUNTIFS('Game History'!G:G,"MRDA",'Game History'!H:H,"Playoff",'Game History'!I:I,Instructions!A79) -> 0 | L39: =COUNTIFS('Game History'!G:G,"MRDA",'Game History'!H:H,"Sanc",'Game History'!I:I,Instructions!A79) -> 0 | M39: =COUNTIFS('Game History'!G:G,"MRDA",'Game History'!H:H,"Reg",'Game History'!I:I,Instructions!A79) -> 0 | N39: =COUNTIFS('Game History'!G:G,"MRDA",'Game History'!H:H,"Other",'Game History'!I:I,Instructions!A79) -> 0
A40: Alternate Referee | C40: ALTR | D40: =COUNTIFS('Game History'!G:G,"MRDA",'Game History'!H:H,"Champs",'Game History'!I:I,Instructions!A87)+COUNTIFS('Game History'!G:G,"MRDA",'Game History'!H:H,"Playoff",'Game History'!I:I,Instructions!A87) -> 0 | E40: =COUNTIFS('Game History'!G:G,"MRDA",'Game History'!H:H,"Sanc",'Game History'!I:I,Instructions!A87) -> 0 | F40: =COUNTIFS('Game History'!G:G,"MRDA",'Game History'!H:H,"Reg",'Game History'!I:I,Instructions!A87) -> 0 | G40: =COUNTIFS('Game History'!G:G,"MRDA",'Game History'!H:H,"Other",'Game History'!I:I,Instructions!A87) -> 0 | I40: Outside White Board | J40: OWB | K40: =COUNTIFS('Game History'!G:G,"MRDA",'Game History'!H:H,"Champs",'Game History'!I:I,Instructions!A80)+COUNTIFS('Game History'!G:G,"MRDA",'Game History'!H:H,"Playoff",'Game History'!I:I,Instructions!A80) -> 0 | L40: =COUNTIFS('Game History'!G:G,"MRDA",'Game History'!H:H,"Sanc",'Game History'!I:I,Instructions!A80) -> 0 | M40: =COUNTIFS('Game History'!G:G,"MRDA",'Game History'!H:H,"Reg",'Game History'!I:I,Instructions!A80) -> 0 | N40: =COUNTIFS('Game History'!G:G,"MRDA",'Game History'!H:H,"Other",'Game History'!I:I,Instructions!A80) -> 0
A41: Total Referee | D41: =SUM(D36:D40) -> 0 | E41: =SUM(E36:E40) -> 0 | F41: =SUM(F36:F40) -> 0 | G41: =SUM(G36:G40) -> 0 | I41: Jam Timer | J41: JT | K41: =COUNTIFS('Game History'!G:G,"MRDA",'Game History'!H:H,"Champs",'Game History'!I:I,Instructions!A81)+COUNTIFS('Game History'!G:G,"MRDA",'Game History'!H:H,"Playoff",'Game History'!I:I,Instructions!A81) -> 0 | L41: =COUNTIFS('Game History'!G:G,"MRDA",'Game History'!H:H,"Sanc",'Game History'!I:I,Instructions!A81) -> 0 | M41: =COUNTIFS('Game History'!G:G,"MRDA",'Game History'!H:H,"Reg",'Game History'!I:I,Instructions!A81) -> 0 | N41: =COUNTIFS('Game History'!G:G,"MRDA",'Game History'!H:H,"Other",'Game History'!I:I,Instructions!A81) -> 0
I42: Scorekeeper | J42: SK | K42: =COUNTIFS('Game History'!G:G,"MRDA",'Game History'!H:H,"Champs",'Game History'!I:I,Instructions!A82)+COUNTIFS('Game History'!G:G,"MRDA",'Game History'!H:H,"Playoff",'Game History'!I:I,Instructions!A82) -> 0 | L42: =COUNTIFS('Game History'!G:G,"MRDA",'Game History'!H:H,"Sanc",'Game History'!I:I,Instructions!A82) -> 0 | M42: =COUNTIFS('Game History'!G:G,"MRDA",'Game History'!H:H,"Reg",'Game History'!I:I,Instructions!A82) -> 0 | N42: =COUNTIFS('Game History'!G:G,"MRDA",'Game History'!H:H,"Other",'Game History'!I:I,Instructions!A82) -> 0
A43: Tournament Head Referee | C43: THR | D43: =COUNTIFS('Game History'!G:G,"MRDA",'Game History'!H:H,"Champs",'Game History'!I:I,Instructions!A68)+COUNTIFS('Game History'!G:G,"MRDA",'Game History'!H:H,"Playoff",'Game History'!I:I,Instructions!A68) -> 0 | E43: =COUNTIFS('Game History'!G:G,"MRDA",'Game History'!H:H,"Sanc",'Game History'!I:I,Instructions!A68) -> 0 | F43: =COUNTIFS('Game History'!G:G,"MRDA",'Game History'!H:H,"Reg",'Game History'!I:I,Instructions!A68) -> 0 | G43: =COUNTIFS('Game History'!G:G,"MRDA",'Game History'!H:H,"Other",'Game History'!I:I,Instructions!A68) -> 0 | I43: Scoreboard Operator | J43: SO | K43: =COUNTIFS('Game History'!G:G,"MRDA",'Game History'!H:H,"Champs",'Game History'!I:I,Instructions!A83)+COUNTIFS('Game History'!G:G,"MRDA",'Game History'!H:H,"Playoff",'Game History'!I:I,Instructions!A83) -> 0 | L43: =COUNTIFS('Game History'!G:G,"MRDA",'Game History'!H:H,"Sanc",'Game History'!I:I,Instructions!A83) -> 0 | M43: =COUNTIFS('Game History'!G:G,"MRDA",'Game History'!H:H,"Reg",'Game History'!I:I,Instructions!A83) -> 0 | N43: =COUNTIFS('Game History'!G:G,"MRDA",'Game History'!H:H,"Other",'Game History'!I:I,Instructions!A83) -> 0
A44: Crew Head Referee | C44: CHR | D44: =COUNTIFS('Game History'!G:G,"MRDA",'Game History'!H:H,"Champs",'Game History'!I:I,Instructions!A69)+COUNTIFS('Game History'!G:G,"MRDA",'Game History'!H:H,"Playoff",'Game History'!I:I,Instructions!A69)+COUNTIFS('Game History'!G:G,"MRDA",'Game History'!H:H,"Champs",'Game History'!I:I,Instructions!A70)+COUNTIFS('Game History'!G:G,"MRDA",'Game History'!H:H,"Playoff",'Game History'!I:I,Instructions!A70) -> 0 | E44: =COUNTIFS('Game History'!G:G,"MRDA",'Game History'!H:H,"Sanc",'Game History'!I:I,Instructions!A69) -> 0 | F44: =COUNTIFS('Game History'!G:G,"MRDA",'Game History'!H:H,"Reg",'Game History'!I:I,Instructions!A69) -> 0 | G44: =COUNTIFS('Game History'!G:G,"MRDA",'Game History'!H:H,"Other",'Game History'!I:I,Instructions!A69) -> 0 | I44: Penalty Box Manager | J44: PBM | K44: =COUNTIFS('Game History'!G:G,"MRDA",'Game History'!H:H,"Champs",'Game History'!I:I,Instructions!A84)+COUNTIFS('Game History'!G:G,"MRDA",'Game History'!H:H,"Playoff",'Game History'!I:I,Instructions!A84) -> 0 | L44: =COUNTIFS('Game History'!G:G,"MRDA",'Game History'!H:H,"Sanc",'Game History'!I:I,Instructions!A84) -> 0 | M44: =COUNTIFS('Game History'!G:G,"MRDA",'Game History'!H:H,"Reg",'Game History'!I:I,Instructions!A84) -> 0 | N44: =COUNTIFS('Game History'!G:G,"MRDA",'Game History'!H:H,"Other",'Game History'!I:I,Instructions!A84) -> 0
...

Sheet Game History
B1: Game and Officiating Position History
B2: Event Details | D2: Leagues and Teams | I2: Game Specifics | L2: Head Referee/Witness | M2: Head NSO/Witness | N2: Notes
A3: Date | B3: Tournament | C3: Location | D3: Host League | E3: Home Team/Higher Seed | F3: Visiting Team/Lower Seed | G3: Assoc | H3: Type | I3: Position | J3: HO 2nd Position (if applicable) | K3: Positional Software Operator?
A4: 44807 | B4: 5x5 | C4: Blue Mountains, NSW, Australia | D4: Blue Mountains Roller Derby League | E4: Sydney Roller Derby League (Velociraptors) | F4: Newcastle Roller Derby League | G4: WFTDA | H4: Reg | I4: SK | L4: John Ref Kennedy
A5: 44822 | B5: Inner West 10th Birthday | C5: Sydney Boys High, Sydney | D5: Inner West Roller Derby League | E5: Inner West Roller Derby League | F5: Northern Beaches Roller Derby League | G5: WFTDA | H5: Reg | I5: LT | L5: John Ref Kennedy | M5: Ritual Ideas | N5: Joint PT/LT position
A6: 44822 | B6: Inner West 10th Birthday | C6: Sydney Boys High, Sydney | D6: Inner West Roller Derby League | E6: Sydney Roller Derby League (Velociraptors) | F6: Inner West Roller Derby League | G6: WFTDA | H6: Reg | I6: PBM | L6: The Spanish Inquisition | M6: Ritual Ideas
A7: 44822 | B7: Inner West 10th Birthday | C7: Sydney Boys High, Sydney | D7: Inner West Roller Derby League | E7: Sydney Roller Derby League (Velociraptors) | F7: Inner West Roller Derby League | G7: WFTDA | H7: Reg | I7: PBM | L7: John Ref Kennedy | M7: Ritual Ideas
A8: 44863 | B8: 5x5 | C8: Windsor, NSW | D8: Blue Mountains Roller Derby League | E8: Central Coast Roller Derby League / S2D2 | F8: Northern Beaches Roller Derby League | G8: WFTDA | H8: Reg | I8: PBT | L8: Clareful Consideration | M8: Bellows
A9: 44863 | B9: 5x5 | C9: Windsor, NSW | D9: Blue Mountains Roller Derby League | E9: Sydney Roller Derby League (Velociraptors) | F9: Canberra Roller Derby League / Varsity Roller Derby League | G9: WFTDA | H9: Reg | I9: SK | L9: Jim Peccable | M9: Leo Slayer
A10: 44878 | B10: Jurassic Packs | C10: Bass Hill Velodrome, Sydney | D10: Sydney Roller Derby League | E10: Potluck | F10: Potluck | G10: WFTDA | H10: Other | I10: SK | L10: Denominator | M10: Nasty Surprise
A11: 44878 | B11: Jurassic Packs | C11: Bass Hill Velodrome, Sydney Australia | D11: Sydney Roller Derby League | E11: Potluck | F11: Potluck | G11: WFTDA | H11: Other | I11: SO | L11: Bones | M11: Ritual Ideas
A12: 44878 | B12: Jurassic Packs | C12: Bass Hill Velodrome, Sydney Australia | D12: Sydney Roller Derby League | E12: Potluck | F12: Potluck | G12: WFTDA | H12: Other | I12: PT | L12: The Spanish Inquisition | M12: Sparkles | N12: Joint PT/LT position
A13: 44974 | B13: Pride Fight | C13: Sydney | D13: Sydney Roller Derby League | E13: Rainbows | F13: Sparkles | G13: WFTDA | H13: Other | I13: PBT | L13: The Spanish Inquisition | M13: Ritual Ideas
A14: 44974 | B14: Pride Fight | C14: Sydney | D14: Sydney Roller Derby League | E14: Butch | F14: Femme | G14: WFTDA | H14: Other | I14: PT | L14: Denominator | M14: Nasty Surprise | N14: Joint PT/LT position
A15: 45003 | B15: Northern Rivers Revolt | C15: Byron Bay, Australia | D15: Tweed Valley Rollers | E15: Brisbane City Rollers (Red Kennedys) | F15: Sydney Roller Derby League (Snipers) | G15: WFTDA | H15: Reg | I15: PBT | L15: John Ref Kennedy
A16: 45003 | B16: Northern Rivers Revolt | C16: Byron Bay, Australia | D16: Tweed Valley Rollers | E16: Northern Beaches (Sirens) | F16: Van Diemens | G16: WFTDA | H16: Reg | I16: PBT | L16: John Ref Kennedy
A17: 45003 | B17: Northern Rivers Revolt | C17: Byron Bay, Australia | D17: Tweed Valley Rollers | E17: Van Diemens | F17: Sydney Roller Derby League (Snipers) | G17: WFTDA | H17: Reg | I17: PBT | L17: John Ref Kennedy
A18: 45003 | B18: Northern Rivers Revolt | C18: Byron Bay, Australia | D18: Tweed Valley Rollers | E18: South Seas Roller Derby (Banshees) | F18: Northern Beaches Roller Derby (Sirens) | G18: WFTDA | H18: Reg | I18: PBT | L18: John Ref Kennedy
A19: 45004 | B19: Northern Rivers Revolt | C19: Byron Bay, Australia | D19: Tweed Valley Rollers | E19: Brisbane City Rollers (Red Kennedys) | F19: River Valley Rollers | G19: WFTDA | H19: Reg | I19: PBT | L19: John Ref Kennedy
A20: 45004 | B20: Northern Rivers Revolt | C20: Byron Bay, Australia | D20: Tweed Valley Rollers | E20: Sydney Roller Derby League (Velociraptors) | F20: Northern Beaches Roller Derby | G20: WFTDA | H20: Reg | I20: PBT | L20: John Ref Kennedy
A21: 45004 | B21: Northern Rivers Revolt | C21: Byron Bay, Australia | D21: Tweed Valley Rollers | E21: River Valley Rollers | F21: Van Diemens | G21: WFTDA | H21: Reg | I21: PBT | L21: John Ref Kennedy
A22: 45004 | B22: Northern Rivers Revolt | C22: Byron Bay, Australia | D22: Tweed Valley Rollers | E22: Sydney Roller Derby League (Velociraptors) | F22: South Seas Roller Derby (Banshees) | G22: WFTDA | H22: Reg | I22: PBT | L22: John Ref Kennedy
A23: 45031 | B23: 5x5 | C23: Sydney, Australia | D23: Inner West Roller Derby League | E23: Inner West Roller Derby League | F23: Northern Beaches Roller Derby | G23: WFTDA | H23: Reg | I23: SO | L23: Jim Peccable | M23: Ritual Ideas
A24: 45066 | B24: 5x5 | C24: Newcastle, Australia | D24: Newcastle Roller Derby League | E24: Inner West Roller Derby League B | F24: Western Sydney Rollers / South Side Derby | G24: WFTDA | H24: Reg | I24: SO | L24: Clareful Consideration | M24: Vengeful Vixen
A25: 45066 | B25: 5x5 | C25: Newcastle, Australia | D25: Newcastle Roller Derby League | E25: Newcastle Roller Derby League | F25: Inner West Roller Derby League | G25: WFTDA | H25: Reg | I25: PT | L25: Jim Peccable | M25: Seath Lord | N25: Joint PT/LT position
A26: 45081 | B26: 5x5 | C26: Sydney, Australia | D26: Maitland Roller Derby League | E26: Varsity Derby League | F26: Sydney Roller Derby League (Velociraptors) | G26: WFTDA | H26: Reg | I26: JT | L26: Jim Peccable | M26: Leo Slayer
A27: 2023-07-01 | B27: ERRD Smackdown Tournament 2023 | C27: PCYC Hawkesbury - Sydney, Australia | D27: Western Sydney Rollers | E27: CRASH Mixed Gender Roller Derby - The Ultimate Incredibles | F27: Toowoomba City Rollers - Quad Squad | G27: WFTDA | H27: Other | I27: OPR | L27: Clareful Consideration | M27: Body BagHer | N27: THR - John Ref. Kennedy / THNSO - Switzerland
A28: 2023-07-01 | B28: ERRD Smackdown Tournament 2023 | C28: PCYC Hawkesbury - Sydney, Australia | D28: Western Sydney Rollers | E28: Northern Beaches Roller Derby League - Sirens | F28: Sydney Roller Derby League - Velociraptors | G28: WFTDA | H28: Reg | I28: OPR | L28: Clareful Consideration | M28: Body BagHer | N28: THR - John Ref. Kennedy / THNSO - Switzerland
A29: 2023-07-01 | B29: ERRD Smackdown Tournament 2023 | C29: PCYC Hawkesbury - Sydney, Australia | D29: Western Sydney Rollers | E29: Newcastle Roller Derby League - Dockyard Dames | F29: Eastern Region Roller Derby - ERRaDicators | G29: WFTDA | H29: Reg | I29: JR | L29: Clareful Consideration | M29: Body BagHer
A30: 2023-07-01 | B30: ERRD Smackdown Tournament 2023 | C30: PCYC Hawkesbury - Sydney, Australia | D30: Western Sydney Rollers | E30: Northern Beaches Roller Derby League - Sirens | F30: Inner West Roller Derby League - Bamshees | G30: WFTDA | H30: Reg | I30: PT | L30: Jim Peccable | M30: Switzerland | N30: Joint PT/LT position
A31: 2023-07-01 | B31: ERRD Smackdown Tournament 2023 | C31: PCYC Hawkesbury - Sydney, Australia | D31: Western Sydney Rollers | E31: Newcastle Junior Roller Derby - The Combos | F31: Toowoomba City Rollers - Range Rascals | G31: Other | H31: Other | I31: JR | L31: Clareful Consideration | M31: Vixen
A32: 2023-07-01 | B32: ERRD Smackdown Tournament 2023 | C32: PCYC Hawkesbury - Sydney, Australia | D32: Western Sydney Rollers | E32: Wollongong Illawarra Roller Derby League - Steel City Derby Dolls | F32: Central Coast Roller Derby United - Asgardians | G32: WFTDA | H32: Reg | I32: OPR | L32: Jim Peccable | M32: Switzerland
A33: 2023-07-02 | B33: ERRD Smackdown Tournament 2023 | C33: PCYC Hawkesbury - Sydney, Australia | D33: Western Sydney Rollers | E33: Newcastle Roller Derby League - Dockyard Dames | F33: Eastern Region Roller Derby - ERRaDicators | G33: WFTDA | H33: Reg | I33: OPR | L33: Clareful Consideration | M33: Body BagHer
A34: 2023-07-02 | B34: ERRD Smackdown Tournament 2023 | C34: PCYC Hawkesbury - Sydney, Australia | D34: Western Sydney Rollers | E34: CRASH Mixed Gender Roller Derby - The Ultimate Incredibles | F34: Inner West Roller Derby League - Skatecrashers | G34: WFTDA | H34: Other | I34: OPR | L34: Clareful Consideration | M34: Body BagHer
A35: 2023-07-02 | B35: ERRD Smackdown Tournament 2023 | C35: PCYC Hawkesbury - Sydney, Australia | D35: Western Sydney Rollers | E35: Canberra Roller Derby League - Vice City Rollers | F35: CRASH Mixed Gender Roller Derby - The Ultimate Incredibles | G35: WFTDA | H35: Other | I35: OPR | L35: Spanish Inquisition | M35: Dinotello TR2
A36: 2024-07-23 | B36: Fundays Round 1 2023 | C36: Dunc Gray Velodrome, Bass Hill NSW, Australia | D36: Sydney Roller Derby League | E36: The Young and the Rest of Us | F36: Baby got Back Blocks | G36: WFTDA | H36: Other | I36: JR | L36: Spanish Inquisition | M36: Nasty Surprise
A37: 45144 | B37: 5x5 | C37: Sydney, Australia | D37: Inner West Roller Derby League | E37: Northern Beaches (Sirens) | F37: Blue Mountains Roller Derby League | G37: WFTDA | H37: Reg | I37: SK | L37: Snarls Dickens | M37: Even Stephen
A38: 45144 | B38: 5x5 | C38: Sydney, Australia | D38: Inner West Roller Derby League | E38: Newcastle Roller Derby League | F38: Sydney Roller Derby League ( | G38: WFTDA | H38: Reg | I38: JT | L38: Denominator | M38: Seath Lord
A39: 45158 | B39: Fundays Round 2 2023 | C39: Dunc Gray Velodrome, Bass Hill NSW, Australia | D39: Sydney Roller Derby League | E39: A League of their Bones | F39: Baby got Back Blocks | G39: WFTDA | H39: Other | I39: JR
A40: 45178 | B40: 5x5 | C40: Denman Prospect, ACT | D40: Varsity Roller Derby League | E40: Western Sydney Rollers / South Side Derby League | F40: Northern Beaches Roller Derby | G40: WFTDA | H40: Reg | I40: SO | L40: John Ref Kennedy | M40: Leo Slayer
...

Sheet Annuals
A1: Annual Totals by Position
A2: WFTDA Referee
A4: 1 YEAR | B4: Playoff | C4: Sanc | D4: Reg | E4: Total | H4: 18 MONTHS | I4: Playoff | J4: Sanc | K4: Reg | L4: Total
A5: THR | B5: =COUNTIFS('Game History'!A:A,(">"&(TODAY()-365)),'Game History'!G:G,"WFTDA",'Game History'!H:H,"Champs",'Game History'!I:I,Instructions!A68)+COUNTIFS('Game History'!A:A,(">"&(TODAY()-365)),'Game History'!G:G,"WFTDA",'Game History'!H:H,"Playoff",'Game History'!I:I,Instructions!A68) -> 0 | C5: =COUNTIFS('Game History'!A:A,(">"&(TODAY()-365)),'Game History'!G:G,"WFTDA",'Game History'!H:H,"Sanc",'Game History'!I:I,Instructions!A68) -> 0 | D5: =COUNTIFS('Game History'!A:A,(">"&(TODAY()-365)),'Game History'!G:G,"WFTDA",'Game History'!H:H,"Reg",'Game History'!I:I,Instructions!A68) -> 0 | E5: =SUM(B5,C5,D5) -> 0 | H5: THR | I5: =COUNTIFS('Game History'!A:A,(">"&(TODAY()-548)),'Game History'!G:G,"WFTDA",'Game History'!H:H,"Champs",'Game History'!I:I,Instructions!A68)+COUNTIFS('Game History'!A:A,(">"&(TODAY()-548)),'Game History'!G:G,"WFTDA",'Game History'!H:H,"Playoff",'Game History'!I:I,Instructions!A68) -> 0 | J5: =COUNTIFS('Game History'!A:A,(">"&(TODAY()-548)),'Game History'!G:G,"WFTDA",'Game History'!H:H,"Sanc",'Game History'!I:I,Instructions!A68) -> 0 | K5: =COUNTIFS('Game History'!A:A,(">"&(TODAY()-548)),'Game History'!G:G,"WFTDA",'Game History'!H:H,"Reg",'Game History'!I:I,Instructions!A68) -> 0 | L5: =SUM(I5,J5,K5) -> 0
A6: CHR | B6: =COUNTIFS('Game History'!A:A,(">"&(TODAY()-365)),'Game History'!G:G,"WFTDA",'Game History'!H:H,"Champs",'Game History'!I:I,Instructions!A69)+COUNTIFS('Game History'!A:A,(">"&(TODAY()-365)),'Game History'!G:G,"WFTDA",'Game History'!H:H,"Playoff",'Game History'!I:I,Instructions!A69)+COUNTIFS('Game History'!A:A,(">"&(TODAY()-365)),'Game History'!G:G,"WFTDA",'Game History'!H:H,"Champs",'Game History'!I:I,Instructions!A70)+COUNTIFS('Game History'!A:A,(">"&(TODAY()-365)),'Game History'!G:G,"WFTDA",'Game History'!H:H,"Playoff",'Game History'!I:I,Instructions!A70) -> 0 | C6: =COUNTIFS('Game History'!A:A,(">"&(TODAY()-365)),'Game History'!G:G,"WFTDA",'Game History'!H:H,"Sanc",'Game History'!I:I,Instructions!A69) -> 0 | D6: =COUNTIFS('Game History'!A:A,(">"&(TODAY()-365)),'Game History'!G:G,"WFTDA",'Game History'!H:H,"Reg",'Game History'!I:I,Instructions!A69) -> 0 | E6: =SUM(B6,C6,D6) -> 0 | H6: CHR | I6: =COUNTIFS('Game History'!A:A,(">"&(TODAY()-548)),'Game History'!G:G,"WFTDA",'Game History'!H:H,"Champs",'Game History'!I:I,Instructions!A69)+COUNTIFS('Game History'!A:A,(">"&(TODAY()-548)),'Game History'!G:G,"WFTDA",'Game History'!H:H,"Playoff",'Game History'!I:I,Instructions!A69)+COUNTIFS('Game History'!A:A,(">"&(TODAY()-548)),'Game History'!G:G,"WFTDA",'Game History'!H:H,"Champs",'Game History'!I:I,Instructions!A70)+COUNTIFS('Game History'!A:A,(">"&(TODAY()-548)),'Game History'!G:G,"WFTDA",'Game History'!H:H,"Playoff",'Game History'!I:I,Instructions!A70) -> 0 | J6: =COUNTIFS('Game History'!A:A,(">"&(TODAY()-548)),'Game History'!G:G,"WFTDA",'Game History'!H:H,"Sanc",'Game History'!I:I,Instructions!A69) -> 0 | K6: =COUNTIFS('Game History'!A:A,(">"&(TODAY()-548)),'Game History'!G:G,"WFTDA",'Game History'!H:H,"Reg",'Game History'!I:I,Instructions!A69) -> 0 | L6: =SUM(I6,J6,K6) -> 0
A7: HR | B7: — | C7: =COUNTIFS('Game History'!A:A,(">"&(TODAY()-365)),'Game History'!G:G,"WFTDA",'Game History'!H:H,"Sanc",'Game History'!I:I,Instructions!A70) -> 0 | D7: =COUNTIFS('Game History'!A:A,(">"&(TODAY()-365)),'Game History'!G:G,"WFTDA",'Game History'!H:H,"Reg",'Game History'!I:I,Instructions!A70) -> 0 | E7: =SUM(C7+D7) -> 0 | H7: HR | I7: — | J7: =COUNTIFS('Game History'!A:A,(">"&(TODAY()-548)),'Game History'!G:G,"WFTDA",'Game History'!H:H,"Sanc",'Game History'!I:I,Instructions!A70) -> 0 | K7: =COUNTIFS('Game History'!A:A,(">"&(TODAY()-548)),'Game History'!G:G,"WFTDA",'Game History'!H:H,"Reg",'Game History'!I:I,Instructions!A70) -> 0 | L7: =SUM(J7+K7) -> 0
A8: JR | B8: =COUNTIFS('Game History'!A:A,(">"&(TODAY()-365)),'Game History'!G:G,"WFTDA",'Game History'!H:H,"Champs",'Game History'!I:I,Instructions!A74)+COUNTIFS('Game History'!A:A,(">"&(TODAY()-365)),'Game History'!G:G,"WFTDA",'Game History'!H:H,"Playoff",'Game History'!I:I,Instructions!A74)+COUNTIFS('Game History'!A:A,(">"&(TODAY()-365)),'Game History'!G:G,"WFTDA",'Game History'!H:H,"Champs",'Game History'!J:J,Instructions!A74)+COUNTIFS('Game History'!A:A,(">"&(TODAY()-365)),'Game History'!G:G,"WFTDA",'Game History'!H:H,"Playoff",'Game History'!J:J,Instructions!A74) -> 0 | C8: =COUNTIFS('Game History'!A:A,(">"&(TODAY()-365)),'Game History'!G:G,"WFTDA",'Game History'!H:H,"Sanc",'Game History'!I:I,Instructions!A74)+COUNTIFS('Game History'!A:A,(">"&(TODAY()-365)),'Game History'!G:G,"WFTDA",'Game History'!H:H,"Sanc",'Game History'!J:J,Instructions!A74) -> 0 | D8: =COUNTIFS('Game History'!A:A,(">"&(TODAY()-365)),'Game History'!G:G,"WFTDA",'Game History'!H:H,"Reg",'Game History'!I:I,Instructions!A74)+COUNTIFS('Game History'!A:A,(">"&(TODAY()-365)),'Game History'!G:G,"WFTDA",'Game History'!H:H,"Reg",'Game History'!J:J,Instructions!A74) -> 0 | E8: =SUM(B8,C8,D8) -> 0 | H8: JR | I8: =COUNTIFS('Game History'!A:A,(">"&(TODAY()-548)),'Game History'!G:G,"WFTDA",'Game History'!H:H,"Champs",'Game History'!I:I,Instructions!A74)+COUNTIFS('Game History'!A:A,(">"&(TODAY()-548)),'Game History'!G:G,"WFTDA",'Game History'!H:H,"Playoff",'Game History'!I:I,Instructions!A74)+COUNTIFS('Game History'!A:A,(">"&(TODAY()-548)),'Game History'!G:G,"WFTDA",'Game History'!H:H,"Champs",'Game History'!J:J,Instructions!A74)+COUNTIFS('Game History'!A:A,(">"&(TODAY()-548)),'Game History'!G:G,"WFTDA",'Game History'!H:H,"Playoff",'Game History'!J:J,Instructions!A74) -> 0 | J8: =COUNTIFS('Game History'!A:A,(">"&(TODAY()-548)),'Game History'!G:G,"WFTDA",'Game History'!H:H,"Sanc",'Game History'!I:I,Instructions!A74)+COUNTIFS('Game History'!A:A,(">"&(TODAY()-548)),'Game History'!G:G,"WFTDA",'Game History'!H:H,"Sanc",'Game History'!J:J,Instructions!A74) -> 0 | K8: =COUNTIFS('Game History'!A:A,(">"&(TODAY()-548)),'Game History'!G:G,"WFTDA",'Game History'!H:H,"Reg",'Game History'!I:I,Instructions!A74)+COUNTIFS('Game History'!A:A,(">"&(TODAY()-548)),'Game History'!G:G,"WFTDA",'Game History'!H:H,"Reg",'Game History'!J:J,Instructions!A74) -> 0 | L8: =SUM(I8,J8,K8) -> 0
A9: IPR | B9: =COUNTIFS('Game History'!A:A,(">"&(TODAY()-365)),'Game History'!G:G,"WFTDA",'Game History'!H:H,"Champs",'Game History'!I:I,Instructions!A75)+COUNTIFS('Game History'!A:A,(">"&(TODAY()-365)),'Game History'!G:G,"WFTDA",'Game History'!H:H,"Playoff",'Game History'!I:I,Instructions!A75)+COUNTIFS('Game History'!A:A,(">"&(TODAY()-365)),'Game History'!G:G,"WFTDA",'Game History'!H:H,"Champs",'Game History'!J:J,Instructions!A75)+COUNTIFS('Game History'!A:A,(">"&(TODAY()-365)),'Game History'!G:G,"WFTDA",'Game History'!H:H,"Playoff",'Game History'!J:J,Instructions!A75) -> 0 | C9: =COUNTIFS('Game History'!A:A,(">"&(TODAY()-365)),'Game History'!G:G,"WFTDA",'Game History'!H:H,"Sanc",'Game History'!I:I,Instructions!A75)+COUNTIFS('Game History'!A:A,(">"&(TODAY()-365)),'Game History'!G:G,"WFTDA",'Game History'!H:H,"Sanc",'Game History'!J:J,Instructions!A75) -> 0 | D9: =COUNTIFS('Game History'!A:A,(">"&(TODAY()-365)),'Game History'!G:G,"WFTDA",'Game History'!H:H,"Reg",'Game History'!I:I,Instructions!A75)+COUNTIFS('Game History'!A:A,(">"&(TODAY()-365)),'Game History'!G:G,"WFTDA",'Game History'!H:H,"Reg",'Game History'!J:J,Instructions!A75) -> 0 | E9: =SUM(B9,C9,D9) -> 0 | H9: IPR | I9: =COUNTIFS('Game History'!A:A,(">"&(TODAY()-548)),'Game History'!G:G,"WFTDA",'Game History'!H:H,"Champs",'Game History'!I:I,Instructions!A75)+COUNTIFS('Game History'!A:A,(">"&(TODAY()-548)),'Game History'!G:G,"WFTDA",'Game History'!H:H,"Playoff",'Game History'!I:I,Instructions!A75)+COUNTIFS('Game History'!A:A,(">"&(TODAY()-548)),'Game History'!G:G,"WFTDA",'Game History'!H:H,"Champs",'Game History'!J:J,Instructions!A75)+COUNTIFS('Game History'!A:A,(">"&(TODAY()-548)),'Game History'!G:G,"WFTDA",'Game History'!H:H,"Playoff",'Game History'!J:J,Instructions!A75) -> 0 | J9: =COUNTIFS('Game History'!A:A,(">"&(TODAY()-548)),'Game History'!G:G,"WFTDA",'Game History'!H:H,"Sanc",'Game History'!I:I,Instructions!A75)+COUNTIFS('Game History'!A:A,(">"&(TODAY()-548)),'Game History'!G:G,"WFTDA",'Game History'!H:H,"Sanc",'Game History'!J:J,Instructions!A75) -> 0 | K9: =COUNTIFS('Game History'!A:A,(">"&(TODAY()-548)),'Game History'!G:G,"WFTDA",'Game History'!H:H,"Reg",'Game History'!I:I,Instructions!A75)+COUNTIFS('Game History'!A:A,(">"&(TODAY()-548)),'Game History'!G:G,"WFTDA",'Game History'!H:H,"Reg",'Game History'!J:J,Instructions!A75) -> 0 | L9: =SUM(I9,J9,K9) -> 0
A10: OPR | B10: =COUNTIFS('Game History'!A:A,(">"&(TODAY()-365)),'Game History'!G:G,"WFTDA",'Game History'!H:H,"Champs",'Game History'!I:I,Instructions!A76)+COUNTIFS('Game History'!A:A,(">"&(TODAY()-365)),'Game History'!G:G,"WFTDA",'Game History'!H:H,"Playoff",'Game History'!I:I,Instructions!A76)+COUNTIFS('Game History'!A:A,(">"&(TODAY()-365)),'Game History'!G:G,"WFTDA",'Game History'!H:H,"Champs",'Game History'!J:J,Instructions!A76)+COUNTIFS('Game History'!A:A,(">"&(TODAY()-365)),'Game History'!G:G,"WFTDA",'Game History'!H:H,"Playoff",'Game History'!J:J,Instructions!A76) -> 0 | C10: =COUNTIFS('Game History'!A:A,(">"&(TODAY()-365)),'Game History'!G:G,"WFTDA",'Game History'!H:H,"Sanc",'Game History'!I:I,Instructions!A76)+COUNTIFS('Game History'!A:A,(">"&(TODAY()-365)),'Game History'!G:G,"WFTDA",'Game History'!H:H,"Sanc",'Game History'!J:J,Instructions!A76) -> 0 | D10: =COUNTIFS('Game History'!A:A,(">"&(TODAY()-365)),'Game History'!G:G,"WFTDA",'Game History'!H:H,"Reg",'Game History'!I:I,Instructions!A76)+COUNTIFS('Game History'!A:A,(">"&(TODAY()-365)),'Game History'!G:G,"WFTDA",'Game History'!H:H,"Reg",'Game History'!J:J,Instructions!A76) -> 0 | E10: =SUM(B10,C10,D10) -> 0 | H10: OPR | I10: =COUNTIFS('Game History'!A:A,(">"&(TODAY()-548)),'Game History'!G:G,"WFTDA",'Game History'!H:H,"Champs",'Game History'!I:I,Instructions!A76)+COUNTIFS('Game History'!A:A,(">"&(TODAY()-548)),'Game History'!G:G,"WFTDA",'Game History'!H:H,"Playoff",'Game History'!I:I,Instructions!A76)+COUNTIFS('Game History'!A:A,(">"&(TODAY()-548)),'Game History'!G:G,"WFTDA",'Game History'!H:H,"Champs",'Game History'!J:J,Instructions!A76)+COUNTIFS('Game History'!A:A,(">"&(TODAY()-548)),'Game History'!G:G,"WFTDA",'Game History'!H:H,"Playoff",'Game History'!J:J,Instructions!A76) -> 0 | J10: =COUNTIFS('Game History'!A:A,(">"&(TODAY()-548)),'Game History'!G:G,"WFTDA",'Game History'!H:H,"Sanc",'Game History'!I:I,Instructions!A76)+COUNTIFS('Game History'!A:A,(">"&(TODAY()-548)),'Game History'!G:G,"WFTDA",'Game History'!H:H,"Sanc",'Game History'!J:J,Instructions!A76) -> 0 | K10: =COUNTIFS('Game History'!A:A,(">"&(TODAY()-548)),'Game History'!G:G,"WFTDA",'Game History'!H:H,"Reg",'Game History'!I:I,Instructions!A76)+COUNTIFS('Game History'!A:A,(">"&(TODAY()-548)),'Game History'!G:G,"WFTDA",'Game History'!H:H,"Reg",'Game History'!J:J,Instructions!A76) -> 0 | L10: =SUM(I10,J10,K10) -> 0
A11: ALT | B11: =COUNTIFS('Game History'!A:A,(">"&(TODAY()-365)),'Game History'!G:G,"WFTDA",'Game History'!H:H,"Champs",'Game History'!I:I,Instructions!A87)+COUNTIFS('Game History'!A:A,(">"&(TODAY()-365)),'Game History'!G:G,"WFTDA",'Game History'!H:H,"Playoff",'Game History'!I:I,Instructions!A87) -> 0 | C11: =COUNTIFS('Game History'!A:A,(">"&(TODAY()-365)),'Game History'!G:G,"WFTDA",'Game History'!H:H,"Sanc",'Game History'!I:I,Instructions!A87) -> 0 | D11: =COUNTIFS('Game History'!A:A,(">"&(TODAY()-365)),'Game History'!G:G,"WFTDA",'Game History'!H:H,"Reg",'Game History'!I:I,Instructions!A87) -> 0 | E11: =SUM(B11,C11,D11) -> 0 | H11: ALT | I11: =COUNTIFS('Game History'!A:A,(">"&(TODAY()-548)),'Game History'!G:G,"WFTDA",'Game History'!H:H,"Champs",'Game History'!I:I,Instructions!A87)+COUNTIFS('Game History'!A:A,(">"&(TODAY()-548)),'Game History'!G:G,"WFTDA",'Game History'!H:H,"Playoff",'Game History'!I:I,Instructions!A87) -> 0 | J11: =COUNTIFS('Game History'!A:A,(">"&(TODAY()-548)),'Game History'!G:G,"WFTDA",'Game History'!H:H,"Sanc",'Game History'!I:I,Instructions!A87) -> 0 | K11: =COUNTIFS('Game History'!A:A,(">"&(TODAY()-548)),'Game History'!G:G,"WFTDA",'Game History'!H:H,"Reg",'Game History'!I:I,Instructions!A87) -> 0 | L11: =SUM(I11,J11,K11) -> 0
A12: Total* | B12: =SUM(B5:B11) -> 0 | C12: =SUM(C5:C11) -> 0 | D12: =SUM(D5:D11) -> 0 | E12: =SUM(E5:E11) -> 0 | H12: Total* | I12: =SUM(I5:I11) -> 0 | J12: =SUM(J5:J11) -> 0 | K12: =SUM(K5:K11) -> 0 | L12: =SUM(L5:L11) -> 0
A15: WFTDA Non-Skating Official
A17: 1 YEAR | B17: Playoff | C17: Sanc | D17: Reg | E17: Total | H17: 18 MONTHS | I17: Playoff | J17: Sanc | K17: Reg | L17: Total
A18: THNSO | B18: =COUNTIFS('Game History'!A:A,(">"&(TODAY()-365)),'Game History'!G:G,"WFTDA",'Game History'!H:H,"Champs",'Game History'!I:I,Instructions!A71)+COUNTIFS('Game History'!A:A,(">"&(TODAY()-365)),'Game History'!G:G,"WFTDA",'Game History'!H:H,"Playoff",'Game History'!I:I,Instructions!A71) -> 0 | C18: =COUNTIFS('Game History'!A:A,(">"&(TODAY()-365)),'Game History'!G:G,"WFTDA",'Game History'!H:H,"Sanc",'Game History'!I:I,Instructions!A71) -> 0 | D18: =COUNTIFS('Game History'!A:A,(">"&(TODAY()-365)),'Game History'!G:G,"WFTDA",'Game History'!H:H,"Reg",'Game History'!I:I,Instructions!A71) -> 0 | E18: =SUM(B18+C18+D18) -> 0 | H18: THNSO | I18: =COUNTIFS('Game History'!A:A,(">"&(TODAY()-548)),'Game History'!G:G,"WFTDA",'Game History'!H:H,"Champs",'Game History'!I:I,Instructions!A71)+COUNTIFS('Game History'!A:A,(">"&(TODAY()-548)),'Game History'!G:G,"WFTDA",'Game History'!H:H,"Playoff",'Game History'!I:I,Instructions!A71) -> 0 | J18: =COUNTIFS('Game History'!A:A,(">"&(TODAY()-548)),'Game History'!G:G,"WFTDA",'Game History'!H:H,"Sanc",'Game History'!I:I,Instructions!A71) -> 0 | K18: =COUNTIFS('Game History'!A:A,(">"&(TODAY()-548)),'Game History'!G:G,"WFTDA",'Game History'!H:H,"Reg",'Game History'!I:I,Instructions!A71) -> 0 | L18: =SUM(I18+J18+K18) -> 0
A19: CHNSO | B19: =COUNTIFS('Game History'!A:A,(">"&(TODAY()-365)),'Game History'!G:G,"WFTDA",'Game History'!H:H,"Champs",'Game History'!I:I,Instructions!A72)+COUNTIFS('Game History'!A:A,(">"&(TODAY()-365)),'Game History'!G:G,"WFTDA",'Game History'!H:H,"Playoff",'Game History'!I:I,Instructions!A72)+COUNTIFS('Game History'!A:A,(">"&(TODAY()-365)),'Game History'!G:G,"WFTDA",'Game History'!H:H,"Champs",'Game History'!I:I,Instructions!A73)+COUNTIFS('Game History'!A:A,(">"&(TODAY()-365)),'Game History'!G:G,"WFTDA",'Game History'!H:H,"Playoff",'Game History'!I:I,Instructions!A73) -> 0 | C19: =COUNTIFS('Game History'!A:A,(">"&(TODAY()-365)),'Game History'!G:G,"WFTDA",'Game History'!H:H,"Sanc",'Game History'!I:I,Instructions!A72) -> 0 | D19: =COUNTIFS('Game History'!A:A,(">"&(TODAY()-365)),'Game History'!G:G,"WFTDA",'Game History'!H:H,"Reg",'Game History'!I:I,Instructions!A72) -> 0 | E19: =SUM(B19+C19+D19) -> 0 | H19: CHNSO | I19: =COUNTIFS('Game History'!A:A,(">"&(TODAY()-548)),'Game History'!G:G,"WFTDA",'Game History'!H:H,"Champs",'Game History'!I:I,Instructions!A72)+COUNTIFS('Game History'!A:A,(">"&(TODAY()-548)),'Game History'!G:G,"WFTDA",'Game History'!H:H,"Playoff",'Game History'!I:I,Instructions!A72)+COUNTIFS('Game History'!A:A,(">"&(TODAY()-548)),'Game History'!G:G,"WFTDA",'Game History'!H:H,"Champs",'Game History'!I:I,Instructions!A73)+COUNTIFS('Game History'!A:A,(">"&(TODAY()-548)),'Game History'!G:G,"WFTDA",'Game History'!H:H,"Playoff",'Game History'!I:I,Instructions!A73) -> 0 | J19: =COUNTIFS('Game History'!A:A,(">"&(TODAY()-548)),'Game History'!G:G,"WFTDA",'Game History'!H:H,"Sanc",'Game History'!I:I,Instructions!A72) -> 0 | K19: =COUNTIFS('Game History'!A:A,(">"&(TODAY()-548)),'Game History'!G:G,"WFTDA",'Game History'!H:H,"Reg",'Game History'!I:I,Instructions!A72) -> 0 | L19: =SUM(I19+J19+K19) -> 0
A20: HNSO | B20: — | C20: =COUNTIFS('Game History'!A:A,(">"&(TODAY()-365)),'Game History'!G:G,"WFTDA",'Game History'!H:H,"Sanc",'Game History'!I:I,Instructions!A73) -> 0 | D20: =COUNTIFS('Game History'!A:A,(">"&(TODAY()-365)),'Game History'!G:G,"WFTDA",'Game History'!H:H,"Reg",'Game History'!I:I,Instructions!A73) -> 0 | E20: =SUM(C20+D20) -> 0 | F20: Operator | H20: HNSO | I20: — | J20: =COUNTIFS('Game History'!A:A,(">"&(TODAY()-548)),'Game History'!G:G,"WFTDA",'Game History'!H:H,"Sanc",'Game History'!I:I,Instructions!A73) -> 0 | K20: =COUNTIFS('Game History'!A:A,(">"&(TODAY()-548)),'Game History'!G:G,"WFTDA",'Game History'!H:H,"Reg",'Game History'!I:I,Instructions!A73) -> 0 | L20: =SUM(J20+K20) -> 0 | M20: Operator
A21: PT | B21: =COUNTIFS('Game History'!A:A,(">"&(TODAY()-365)),'Game History'!G:G,"WFTDA",'Game History'!H:H,"Champs",'Game History'!I:I,Instructions!A77)+COUNTIFS('Game History'!A:A,(">"&(TODAY()-365)),'Game History'!G:G,"WFTDA",'Game History'!H:H,"Playoff",'Game History'!I:I,Instructions!A77)+COUNTIFS('Game History'!A:A,(">"&(TODAY()-365)),'Game History'!G:G,"WFTDA",'Game History'!H:H,"Champs",'Game History'!J:J,Instructions!A77)+COUNTIFS('Game History'!A:A,(">"&(TODAY()-365)),'Game History'!G:G,"WFTDA",'Game History'!H:H,"Playoff",'Game History'!J:J,Instructions!A77) -> 0 | C21: =COUNTIFS('Game History'!A:A,(">"&(TODAY()-365)),'Game History'!G:G,"WFTDA",'Game History'!H:H,"Sanc",'Game History'!I:I,Instructions!A77)+COUNTIFS('Game History'!A:A,(">"&(TODAY()-365)),'Game History'!G:G,"WFTDA",'Game History'!H:H,"Sanc",'Game History'!J:J,Instructions!A77) -> 0 | D21: =COUNTIFS('Game History'!A:A,(">"&(TODAY()-365)),'Game History'!G:G,"WFTDA",'Game History'!H:H,"Reg",'Game History'!I:I,Instructions!A77)+COUNTIFS('Game History'!A:A,(">"&(TODAY()-365)),'Game History'!G:G,"WFTDA",'Game History'!H:H,"Reg",'Game History'!J:J,Instructions!A77) -> 0 | E21: =SUM(B21+C21+D21) -> 0 | F21: =COUNTIFS('Game History'!A:A,(">"&(TODAY()-365)),'Game History'!G:G,"WFTDA",'Game History'!I:I,A21,'Game History'!K:K,"Y")+COUNTIFS('Game History'!A:A,(">"&(TODAY()-365)),'Game History'!G:G,"WFTDA",'Game History'!J:J,A21,'Game History'!K:K,"Y") -> 0 | H21: PT | I21: =COUNTIFS('Game History'!A:A,(">"&(TODAY()-548)),'Game History'!G:G,"WFTDA",'Game History'!H:H,"Champs",'Game History'!I:I,Instructions!A77)+COUNTIFS('Game History'!A:A,(">"&(TODAY()-548)),'Game History'!G:G,"WFTDA",'Game History'!H:H,"Playoff",'Game History'!I:I,Instructions!A77)+COUNTIFS('Game History'!A:A,(">"&(TODAY()-548)),'Game History'!G:G,"WFTDA",'Game History'!H:H,"Champs",'Game History'!J:J,Instructions!A77)+COUNTIFS('Game History'!A:A,(">"&(TODAY()-548)),'Game History'!G:G,"WFTDA",'Game History'!H:H,"Playoff",'Game History'!J:J,Instructions!A77) -> 0 | J21: =COUNTIFS('Game History'!A:A,(">"&(TODAY()-548)),'Game History'!G:G,"WFTDA",'Game History'!H:H,"Sanc",'Game History'!I:I,Instructions!A77)+COUNTIFS('Game History'!A:A,(">"&(TODAY()-548)),'Game History'!G:G,"WFTDA",'Game History'!H:H,"Sanc",'Game History'!J:J,Instructions!A77) -> 0 | K21: =COUNTIFS('Game History'!A:A,(">"&(TODAY()-548)),'Game History'!G:G,"WFTDA",'Game History'!H:H,"Reg",'Game History'!I:I,Instructions!A77)+COUNTIFS('Game History'!A:A,(">"&(TODAY()-548)),'Game History'!G:G,"WFTDA",'Game History'!H:H,"Reg",'Game History'!J:J,Instructions!A77) -> 0 | L21: =SUM(I21+J21+K21) -> 0 | M21: =COUNTIFS('Game History'!A:A,(">"&(TODAY()-548)),'Game History'!G:G,"WFTDA",'Game History'!I:I,A21,'Game History'!K:K,"Y")+COUNTIFS('Game History'!A:A,(">"&(TODAY()-548)),'Game History'!G:G,"WFTDA",'Game History'!J:J,A21,'Game History'!K:K,"Y") -> 0
A22: PW | B22: =COUNTIFS('Game History'!A:A,(">"&(TODAY()-365)),'Game History'!G:G,"WFTDA",'Game History'!H:H,"Champs",'Game History'!I:I,Instructions!A78)+COUNTIFS('Game History'!A:A,(">"&(TODAY()-365)),'Game History'!G:G,"WFTDA",'Game History'!H:H,"Playoff",'Game History'!I:I,Instructions!A78)+COUNTIFS('Game History'!A:A,(">"&(TODAY()-365)),'Game History'!G:G,"WFTDA",'Game History'!H:H,"Champs",'Game History'!J:J,Instructions!A78)+COUNTIFS('Game History'!A:A,(">"&(TODAY()-365)),'Game History'!G:G,"WFTDA",'Game History'!H:H,"Playoff",'Game History'!J:J,Instructions!A78) -> 0 | C22: =COUNTIFS('Game History'!A:A,(">"&(TODAY()-365)),'Game History'!G:G,"WFTDA",'Game History'!H:H,"Sanc",'Game History'!I:I,Instructions!A78)+COUNTIFS('Game History'!A:A,(">"&(TODAY()-365)),'Game History'!G:G,"WFTDA",'Game History'!H:H,"Sanc",'Game History'!J:J,Instructions!A78) -> 0 | D22: =COUNTIFS('Game History'!A:A,(">"&(TODAY()-365)),'Game History'!G:G,"WFTDA",'Game History'!H:H,"Reg",'Game History'!I:I,Instructions!A78)+COUNTIFS('Game History'!A:A,(">"&(TODAY()-365)),'Game History'!G:G,"WFTDA",'Game History'!H:H,"Reg",'Game History'!J:J,Instructions!A78) -> 0 | E22: =SUM(B22+C22+D22) -> 0 | F22: =COUNTIFS('Game History'!A:A,(">"&(TODAY()-365)),'Game History'!G:G,"WFTDA",'Game History'!I:I,A22,'Game History'!K:K,"Y")+COUNTIFS('Game History'!A:A,(">"&(TODAY()-365)),'Game History'!G:G,"WFTDA",'Game History'!J:J,A22,'Game History'!K:K,"Y") -> 0 | H22: PW | I22: =COUNTIFS('Game History'!A:A,(">"&(TODAY()-548)),'Game History'!G:G,"WFTDA",'Game History'!H:H,"Champs",'Game History'!I:I,Instructions!A78)+COUNTIFS('Game History'!A:A,(">"&(TODAY()-548)),'Game History'!G:G,"WFTDA",'Game History'!H:H,"Playoff",'Game History'!I:I,Instructions!A78)+COUNTIFS('Game History'!A:A,(">"&(TODAY()-548)),'Game History'!G:G,"WFTDA",'Game History'!H:H,"Champs",'Game History'!J:J,Instructions!A78)+COUNTIFS('Game History'!A:A,(">"&(TODAY()-548)),'Game History'!G:G,"WFTDA",'Game History'!H:H,"Playoff",'Game History'!J:J,Instructions!A78) -> 0 | J22: =COUNTIFS('Game History'!A:A,(">"&(TODAY()-548)),'Game History'!G:G,"WFTDA",'Game History'!H:H,"Sanc",'Game History'!I:I,Instructions!A78)+COUNTIFS('Game History'!A:A,(">"&(TODAY()-548)),'Game History'!G:G,"WFTDA",'Game History'!H:H,"Sanc",'Game History'!J:J,Instructions!A78) -> 0 | K22: =COUNTIFS('Game History'!A:A,(">"&(TODAY()-548)),'Game History'!G:G,"WFTDA",'Game History'!H:H,"Reg",'Game History'!I:I,Instructions!A78)+COUNTIFS('Game History'!A:A,(">"&(TODAY()-548)),'Game History'!G:G,"WFTDA",'Game History'!H:H,"Reg",'Game History'!J:J,Instructions!A78) -> 0 | L22: =SUM(I22+J22+K22) -> 0 | M22: =COUNTIFS('Game History'!A:A,(">"&(TODAY()-548)),'Game History'!G:G,"WFTDA",'Game History'!I:I,A22,'Game History'!K:K,"Y")+COUNTIFS('Game History'!A:A,(">"&(TODAY()-548)),'Game History'!G:G,"WFTDA",'Game History'!J:J,A22,'Game History'!K:K,"Y") -> 0
A23: IWB | B23: =COUNTIFS('Game History'!A:A,(">"&(TODAY()-365)),'Game History'!G:G,"WFTDA",'Game History'!H:H,"Champs",'Game History'!I:I,Instructions!A79)+COUNTIFS('Game History'!A:A,(">"&(TODAY()-365)),'Game History'!G:G,"WFTDA",'Game History'!H:H,"Playoff",'Game History'!I:I,Instructions!A79)+COUNTIFS('Game History'!A:A,(">"&(TODAY()-365)),'Game History'!G:G,"WFTDA",'Game History'!H:H,"Champs",'Game History'!J:J,Instructions!A79)+COUNTIFS('Game History'!A:A,(">"&(TODAY()-365)),'Game History'!G:G,"WFTDA",'Game History'!H:H,"Playoff",'Game History'!J:J,Instructions!A79) -> 0 | C23: =COUNTIFS('Game History'!A:A,(">"&(TODAY()-365)),'Game History'!G:G,"WFTDA",'Game History'!H:H,"Sanc",'Game History'!I:I,Instructions!A79)+COUNTIFS('Game History'!A:A,(">"&(TODAY()-365)),'Game History'!G:G,"WFTDA",'Game History'!H:H,"Sanc",'Game History'!J:J,Instructions!A79) -> 0 | D23: =COUNTIFS('Game History'!A:A,(">"&(TODAY()-365)),'Game History'!G:G,"WFTDA",'Game History'!H:H,"Reg",'Game History'!I:I,Instructions!A79)+COUNTIFS('Game History'!A:A,(">"&(TODAY()-365)),'Game History'!G:G,"WFTDA",'Game History'!H:H,"Reg",'Game History'!J:J,Instructions!A79) -> 0 | E23: =SUM(B23+C23+D23) -> 0 | F23: =COUNTIFS('Game History'!A:A,(">"&(TODAY()-365)),'Game History'!G:G,"WFTDA",'Game History'!I:I,A23,'Game History'!K:K,"Y")+COUNTIFS('Game History'!A:A,(">"&(TODAY()-365)),'Game History'!G:G,"WFTDA",'Game History'!J:J,A23,'Game History'!K:K,"Y") -> 0 | H23: IWB | I23: =COUNTIFS('Game History'!A:A,(">"&(TODAY()-548)),'Game History'!G:G,"WFTDA",'Game History'!H:H,"Champs",'Game History'!I:I,Instructions!A79)+COUNTIFS('Game History'!A:A,(">"&(TODAY()-548)),'Game History'!G:G,"WFTDA",'Game History'!H:H,"Playoff",'Game History'!I:I,Instructions!A79)+COUNTIFS('Game History'!A:A,(">"&(TODAY()-548)),'Game History'!G:G,"WFTDA",'Game History'!H:H,"Champs",'Game History'!J:J,Instructions!A79)+COUNTIFS('Game History'!A:A,(">"&(TODAY()-548)),'Game History'!G:G,"WFTDA",'Game History'!H:H,"Playoff",'Game History'!J:J,Instructions!A79) -> 0 | J23: =COUNTIFS('Game History'!A:A,(">"&(TODAY()-548)),'Game History'!G:G,"WFTDA",'Game History'!H:H,"Sanc",'Game History'!I:I,Instructions!A79)+COUNTIFS('Game History'!A:A,(">"&(TODAY()-548)),'Game History'!G:G,"WFTDA",'Game History'!H:H,"Sanc",'Game History'!J:J,Instructions!A79) -> 0 | K23: =COUNTIFS('Game History'!A:A,(">"&(TODAY()-548)),'Game History'!G:G,"WFTDA",'Game History'!H:H,"Reg",'Game History'!I:I,Instructions!A79)+COUNTIFS('Game History'!A:A,(">"&(TODAY()-548)),'Game History'!G:G,"WFTDA",'Game History'!H:H,"Reg",'Game History'!J:J,Instructions!A79) -> 0 | L23: =SUM(I23+J23+K23) -> 0 | M23: =COUNTIFS('Game History'!A:A,(">"&(TODAY()-548)),'Game History'!G:G,"WFTDA",'Game History'!I:I,A23,'Game History'!K:K,"Y")+COUNTIFS('Game History'!A:A,(">"&(TODAY()-548)),'Game History'!G:G,"WFTDA",'Game History'!J:J,A23,'Game History'!K:K,"Y") -> 0
